{
 "cells": [
  {
   "cell_type": "markdown",
   "metadata": {},
   "source": [
    "# Step 4: Evaluate Saved Discriminative Model"
   ]
  },
  {
   "cell_type": "markdown",
   "metadata": {},
   "source": [
    "The first thing to do is ensure that modules are auto-reloaded at runtime to allow for development in other files."
   ]
  },
  {
   "cell_type": "code",
   "execution_count": 1,
   "metadata": {},
   "outputs": [],
   "source": [
    "%load_ext autoreload\n",
    "%autoreload 2\n",
    "%matplotlib inline"
   ]
  },
  {
   "cell_type": "markdown",
   "metadata": {},
   "source": [
    "We then set the Snorkel database location and start and connect to it.  By default, we use a PosgreSQL database backend, which can be created using `createdb DB_NAME` once psql is installed.  Note that Snorkel does *not* currently support parallel database processing with a SQLite backend."
   ]
  },
  {
   "cell_type": "code",
   "execution_count": 2,
   "metadata": {},
   "outputs": [],
   "source": [
    "# Setting Snorkel DB location\n",
    "import os\n",
    "import sys\n",
    "\n",
    "import random\n",
    "import numpy as np\n",
    "\n",
    "#For PostgreSQL\n",
    "postgres_location = 'postgresql://jdunnmon:123@localhost:5432'\n",
    "postgres_db_name = 'loc_jd_1M_parsed'\n",
    "os.environ['SNORKELDB'] = os.path.join(postgres_location,postgres_db_name)\n",
    "\n",
    "#For local PostgreSQL\n",
    "#os.environ['SNORKELDB'] = 'postgres:///es_locs_small'\n",
    "\n",
    "# Adding path above for utils\n",
    "sys.path.append('../utils')\n",
    "\n",
    "# For SQLite\n",
    "#db_location = '.'\n",
    "#db_name = \"es_locs_small.db\"\n",
    "#os.environ['SNORKELDB'] = '{0}:///{1}/{2}'.format(\"sqlite\", db_location, db_name)\n",
    "\n",
    "# Start Snorkel session\n",
    "from snorkel import SnorkelSession\n",
    "session = SnorkelSession()\n",
    "\n",
    "# Setting parallelism\n",
    "parallelism = 72\n",
    "\n",
    "# Setting random seed\n",
    "seed = 1701\n",
    "random.seed(seed)\n",
    "np.random.seed(seed)"
   ]
  },
  {
   "cell_type": "code",
   "execution_count": 3,
   "metadata": {},
   "outputs": [
    {
     "name": "stdout",
     "output_type": "stream",
     "text": [
      "Using parallelized loader\n"
     ]
    }
   ],
   "source": [
    "from dataset_utils import set_preprocessor, combine_dedupe\n",
    "\n",
    "# Set data source: options are 'content.tsv', 'memex_jsons', 'es'\n",
    "data_source = 'es'\n",
    "\n",
    "# Setting max number of docs to ingest\n",
    "max_docs = 10000\n",
    "\n",
    "# Setting location of data source\n",
    "\n",
    "# For ES:\n",
    "#data_loc = '/lfs/local/0/jdunnmon/data/chtap/output_all_parsed'\n",
    "#data_loc = '/dfs/scratch0/jdunnmon/data/memex-data/tsvs/output_all_b'\n",
    "data_loc = '/dfs/scratch0/jdunnmon/data/memex-data/tsvs/price/test/shard/parsed'\n",
    "\n",
    "# Optional: add tsv with additional documents to create combined tsv without duplicates\n",
    "#data_loc = combine_dedupe(data_loc, 'output_location.tsv', 'combined.tsv')\n",
    "\n",
    "# If memex_raw_content is a content_field, uses term as a regex in raw data in addition to getting title and body\n",
    "term = r'\\b[Ll]ocation:|\\b[cC]ity:'\n",
    "\n",
    "# Doc length in characters, remove to have no max\n",
    "max_doc_length=10000\n",
    "\n",
    "# Setting preprocessor\n",
    "doc_preprocessor = set_preprocessor(data_source, data_loc, max_docs=max_docs, verbose=True, clean_docs=False,\n",
    "                                    content_fields=['raw_content', 'url'], term=term, max_doc_length=max_doc_length)"
   ]
  },
  {
   "cell_type": "code",
   "execution_count": 17,
   "metadata": {},
   "outputs": [
    {
     "name": "stdout",
     "output_type": "stream",
     "text": [
      "Parsed 1000 docs...\n",
      "Parsed 2000 docs...\n",
      "Parsed 3000 docs...\n",
      "Parsed 4000 docs...\n",
      "Parsed 5000 docs...\n",
      "Parsed 6000 docs...\n",
      "Parsed 7000 docs...\n",
      "Parsed 8000 docs...\n",
      "Parsed 9000 docs...\n",
      "Parsed 10000 docs...\n",
      "Clearing existing...\n",
      "Running UDF...\n",
      "CPU times: user 12.2 s, sys: 472 ms, total: 12.6 s\n",
      "Wall time: 6min 35s\n"
     ]
    }
   ],
   "source": [
    "from snorkel.parser import CorpusParser\n",
    "from snorkel.parser.rule_parser import RegexTokenizer, RuleBasedParser, SpacyTokenizer\n",
    "from snorkel.parser.spacy_parser import Spacy\n",
    "from snorkel.parser.simple_tokenizer import SimpleTokenizer\n",
    "from snorkel.parser.corenlp import StanfordCoreNLPServer\n",
    "\n",
    "# Applying corpus parser\n",
    "#parser = Spacy(annotators=['entity','parser'],\n",
    "#                 lang='en', num_threads=1)\n",
    "#parser = RuleBasedParser(tokenizer=SpacyTokenizer())\n",
    "parser=SimpleTokenizer(delim='<|>')\n",
    "#parser = StanfordCoreNLPServer()\n",
    "corpus_parser = CorpusParser(parser=parser)\n",
    "%time corpus_parser.apply(list(doc_preprocessor), parallelism=16, verbose=True)"
   ]
  },
  {
   "cell_type": "code",
   "execution_count": 4,
   "metadata": {},
   "outputs": [
    {
     "name": "stdout",
     "output_type": "stream",
     "text": [
      "Documents: 10000\n",
      "Sentences: 168660\n"
     ]
    }
   ],
   "source": [
    "from snorkel.models import Document, Sentence\n",
    "\n",
    "# Printing number of docs/sentences\n",
    "print(\"Documents:\", session.query(Document).count())\n",
    "print(\"Sentences:\", session.query(Sentence).count())"
   ]
  },
  {
   "cell_type": "code",
   "execution_count": 43,
   "metadata": {},
   "outputs": [],
   "source": [
    "# Getting all documents parsed by Snorkel\n",
    "docs = session.query(Document).all()\n",
    "sents = session.query(Sentence).all()"
   ]
  },
  {
   "cell_type": "markdown",
   "metadata": {},
   "source": [
    "Create candidate subclass"
   ]
  },
  {
   "cell_type": "code",
   "execution_count": 6,
   "metadata": {},
   "outputs": [],
   "source": [
    "from snorkel.candidates import Ngrams\n",
    "from snorkel.candidates import CandidateExtractor\n",
    "from dataset_utils import create_candidate_class, LocationMatcher, city_index\n",
    "from snorkel.matchers import Union, LambdaFunctionMatcher\n",
    "\n",
    "# Setting extraction type -- should be a subfield in your data source extractions field!\n",
    "extraction_type = 'location'\n",
    "\n",
    "# Creating candidate class\n",
    "candidate_class, candidate_class_name = create_candidate_class(extraction_type)\n",
    "\n",
    "# Defining ngrams for candidates\n",
    "location_ngrams = Ngrams(n_max=3)\n",
    "\n",
    "# Define matchers\n",
    "cities = city_index('../utils/data/cities15000.txt')\n",
    "geo_location_matcher = LambdaFunctionMatcher(func=cities.fast_loc)\n",
    "# spacy_location_matcher = LocationMatcher(longest_match_only=True)\n",
    "\n",
    "# Union matchers and create candidate extractor\n",
    "location_matcher = Union(geo_location_matcher)\n",
    "cand_extractor   = CandidateExtractor(candidate_class, [location_ngrams], [location_matcher])"
   ]
  },
  {
   "cell_type": "code",
   "execution_count": 8,
   "metadata": {},
   "outputs": [
    {
     "name": "stdout",
     "output_type": "stream",
     "text": [
      "Clearing existing...\n",
      "Running UDF...\n"
     ]
    },
    {
     "name": "stderr",
     "output_type": "stream",
     "text": [
      "Process CandidateExtractorUDF-22:\n",
      "Traceback (most recent call last):\n",
      "  File \"/lfs/local/0/jdunnmon/repos/anaconda3/envs/snorkel/lib/python3.6/site-packages/sqlalchemy/engine/base.py\", line 1170, in _execute_context\n",
      "    context)\n",
      "  File \"/lfs/local/0/jdunnmon/repos/anaconda3/envs/snorkel/lib/python3.6/site-packages/sqlalchemy/dialects/postgresql/psycopg2.py\", line 683, in do_executemany\n",
      "    cursor.executemany(statement, parameters)\n",
      "psycopg2.IntegrityError: duplicate key value violates unique constraint \"location_location_id_key\"\n",
      "DETAIL:  Key (location_id)=(239680) already exists.\n",
      "\n",
      "\n",
      "The above exception was the direct cause of the following exception:\n",
      "\n",
      "Traceback (most recent call last):\n",
      "  File \"/lfs/local/0/jdunnmon/repos/anaconda3/envs/snorkel/lib/python3.6/multiprocessing/process.py\", line 258, in _bootstrap\n",
      "    self.run()\n",
      "  File \"/lfs/raiders5/0/jdunnmon/repos/snorkel/snorkel/udf.py\", line 170, in run\n",
      "    self.session.commit()\n",
      "  File \"/lfs/local/0/jdunnmon/repos/anaconda3/envs/snorkel/lib/python3.6/site-packages/sqlalchemy/orm/session.py\", line 943, in commit\n",
      "    self.transaction.commit()\n",
      "  File \"/lfs/local/0/jdunnmon/repos/anaconda3/envs/snorkel/lib/python3.6/site-packages/sqlalchemy/orm/session.py\", line 467, in commit\n",
      "    self._prepare_impl()\n",
      "  File \"/lfs/local/0/jdunnmon/repos/anaconda3/envs/snorkel/lib/python3.6/site-packages/sqlalchemy/orm/session.py\", line 447, in _prepare_impl\n",
      "    self.session.flush()\n",
      "  File \"/lfs/local/0/jdunnmon/repos/anaconda3/envs/snorkel/lib/python3.6/site-packages/sqlalchemy/orm/session.py\", line 2254, in flush\n",
      "    self._flush(objects)\n",
      "  File \"/lfs/local/0/jdunnmon/repos/anaconda3/envs/snorkel/lib/python3.6/site-packages/sqlalchemy/orm/session.py\", line 2380, in _flush\n",
      "    transaction.rollback(_capture_exception=True)\n",
      "  File \"/lfs/local/0/jdunnmon/repos/anaconda3/envs/snorkel/lib/python3.6/site-packages/sqlalchemy/util/langhelpers.py\", line 66, in __exit__\n",
      "    compat.reraise(exc_type, exc_value, exc_tb)\n",
      "  File \"/lfs/local/0/jdunnmon/repos/anaconda3/envs/snorkel/lib/python3.6/site-packages/sqlalchemy/util/compat.py\", line 187, in reraise\n",
      "    raise value\n",
      "  File \"/lfs/local/0/jdunnmon/repos/anaconda3/envs/snorkel/lib/python3.6/site-packages/sqlalchemy/orm/session.py\", line 2344, in _flush\n",
      "    flush_context.execute()\n",
      "  File \"/lfs/local/0/jdunnmon/repos/anaconda3/envs/snorkel/lib/python3.6/site-packages/sqlalchemy/orm/unitofwork.py\", line 391, in execute\n",
      "    rec.execute(self)\n",
      "  File \"/lfs/local/0/jdunnmon/repos/anaconda3/envs/snorkel/lib/python3.6/site-packages/sqlalchemy/orm/unitofwork.py\", line 556, in execute\n",
      "    uow\n",
      "  File \"/lfs/local/0/jdunnmon/repos/anaconda3/envs/snorkel/lib/python3.6/site-packages/sqlalchemy/orm/persistence.py\", line 181, in save_obj\n",
      "    mapper, table, insert)\n",
      "  File \"/lfs/local/0/jdunnmon/repos/anaconda3/envs/snorkel/lib/python3.6/site-packages/sqlalchemy/orm/persistence.py\", line 830, in _emit_insert_statements\n",
      "    execute(statement, multiparams)\n",
      "  File \"/lfs/local/0/jdunnmon/repos/anaconda3/envs/snorkel/lib/python3.6/site-packages/sqlalchemy/engine/base.py\", line 948, in execute\n",
      "    return meth(self, multiparams, params)\n",
      "  File \"/lfs/local/0/jdunnmon/repos/anaconda3/envs/snorkel/lib/python3.6/site-packages/sqlalchemy/sql/elements.py\", line 269, in _execute_on_connection\n",
      "    return connection._execute_clauseelement(self, multiparams, params)\n",
      "  File \"/lfs/local/0/jdunnmon/repos/anaconda3/envs/snorkel/lib/python3.6/site-packages/sqlalchemy/engine/base.py\", line 1060, in _execute_clauseelement\n",
      "    compiled_sql, distilled_params\n",
      "  File \"/lfs/local/0/jdunnmon/repos/anaconda3/envs/snorkel/lib/python3.6/site-packages/sqlalchemy/engine/base.py\", line 1200, in _execute_context\n",
      "    context)\n",
      "  File \"/lfs/local/0/jdunnmon/repos/anaconda3/envs/snorkel/lib/python3.6/site-packages/sqlalchemy/engine/base.py\", line 1413, in _handle_dbapi_exception\n",
      "    exc_info\n",
      "  File \"/lfs/local/0/jdunnmon/repos/anaconda3/envs/snorkel/lib/python3.6/site-packages/sqlalchemy/util/compat.py\", line 203, in raise_from_cause\n",
      "    reraise(type(exception), exception, tb=exc_tb, cause=cause)\n",
      "  File \"/lfs/local/0/jdunnmon/repos/anaconda3/envs/snorkel/lib/python3.6/site-packages/sqlalchemy/util/compat.py\", line 186, in reraise\n",
      "    raise value.with_traceback(tb)\n",
      "  File \"/lfs/local/0/jdunnmon/repos/anaconda3/envs/snorkel/lib/python3.6/site-packages/sqlalchemy/engine/base.py\", line 1170, in _execute_context\n",
      "    context)\n",
      "  File \"/lfs/local/0/jdunnmon/repos/anaconda3/envs/snorkel/lib/python3.6/site-packages/sqlalchemy/dialects/postgresql/psycopg2.py\", line 683, in do_executemany\n",
      "    cursor.executemany(statement, parameters)\n",
      "sqlalchemy.exc.IntegrityError: (psycopg2.IntegrityError) duplicate key value violates unique constraint \"location_location_id_key\"\n",
      "DETAIL:  Key (location_id)=(239680) already exists.\n",
      " [SQL: 'INSERT INTO location (id, location_id, location_cid) VALUES (%(id)s, %(location_id)s, %(location_cid)s)'] [parameters: ({'id': 66459, 'location_id': 239264, 'location_cid': None}, {'id': 66477, 'location_id': 239277, 'location_cid': None}, {'id': 66489, 'location_id': 239281, 'location_cid': None}, {'id': 66509, 'location_id': 239291, 'location_cid': None}, {'id': 66520, 'location_id': 239298, 'location_cid': None}, {'id': 66538, 'location_id': 239299, 'location_cid': None}, {'id': 66555, 'location_id': 239313, 'location_cid': None}, {'id': 66573, 'location_id': 239322, 'location_cid': None}  ... displaying 10 of 5533 total bound parameter sets ...  {'id': 154972, 'location_id': 330133, 'location_cid': None}, {'id': 154986, 'location_id': 330137, 'location_cid': None})] (Background on this error at: http://sqlalche.me/e/gkpj)\n",
      "Process CandidateExtractorUDF-18:\n",
      "Traceback (most recent call last):\n",
      "  File \"/lfs/local/0/jdunnmon/repos/anaconda3/envs/snorkel/lib/python3.6/site-packages/sqlalchemy/engine/base.py\", line 1170, in _execute_context\n",
      "    context)\n",
      "  File \"/lfs/local/0/jdunnmon/repos/anaconda3/envs/snorkel/lib/python3.6/site-packages/sqlalchemy/dialects/postgresql/psycopg2.py\", line 683, in do_executemany\n",
      "    cursor.executemany(statement, parameters)\n",
      "psycopg2.IntegrityError: duplicate key value violates unique constraint \"location_location_id_key\"\n",
      "DETAIL:  Key (location_id)=(239331) already exists.\n",
      "\n",
      "\n",
      "The above exception was the direct cause of the following exception:\n",
      "\n",
      "Traceback (most recent call last):\n",
      "  File \"/lfs/local/0/jdunnmon/repos/anaconda3/envs/snorkel/lib/python3.6/multiprocessing/process.py\", line 258, in _bootstrap\n",
      "    self.run()\n",
      "  File \"/lfs/raiders5/0/jdunnmon/repos/snorkel/snorkel/udf.py\", line 170, in run\n",
      "    self.session.commit()\n",
      "  File \"/lfs/local/0/jdunnmon/repos/anaconda3/envs/snorkel/lib/python3.6/site-packages/sqlalchemy/orm/session.py\", line 943, in commit\n",
      "    self.transaction.commit()\n",
      "  File \"/lfs/local/0/jdunnmon/repos/anaconda3/envs/snorkel/lib/python3.6/site-packages/sqlalchemy/orm/session.py\", line 467, in commit\n",
      "    self._prepare_impl()\n",
      "  File \"/lfs/local/0/jdunnmon/repos/anaconda3/envs/snorkel/lib/python3.6/site-packages/sqlalchemy/orm/session.py\", line 447, in _prepare_impl\n",
      "    self.session.flush()\n",
      "  File \"/lfs/local/0/jdunnmon/repos/anaconda3/envs/snorkel/lib/python3.6/site-packages/sqlalchemy/orm/session.py\", line 2254, in flush\n",
      "    self._flush(objects)\n",
      "  File \"/lfs/local/0/jdunnmon/repos/anaconda3/envs/snorkel/lib/python3.6/site-packages/sqlalchemy/orm/session.py\", line 2380, in _flush\n",
      "    transaction.rollback(_capture_exception=True)\n",
      "  File \"/lfs/local/0/jdunnmon/repos/anaconda3/envs/snorkel/lib/python3.6/site-packages/sqlalchemy/util/langhelpers.py\", line 66, in __exit__\n",
      "    compat.reraise(exc_type, exc_value, exc_tb)\n",
      "  File \"/lfs/local/0/jdunnmon/repos/anaconda3/envs/snorkel/lib/python3.6/site-packages/sqlalchemy/util/compat.py\", line 187, in reraise\n",
      "    raise value\n",
      "  File \"/lfs/local/0/jdunnmon/repos/anaconda3/envs/snorkel/lib/python3.6/site-packages/sqlalchemy/orm/session.py\", line 2344, in _flush\n",
      "    flush_context.execute()\n",
      "  File \"/lfs/local/0/jdunnmon/repos/anaconda3/envs/snorkel/lib/python3.6/site-packages/sqlalchemy/orm/unitofwork.py\", line 391, in execute\n",
      "    rec.execute(self)\n",
      "  File \"/lfs/local/0/jdunnmon/repos/anaconda3/envs/snorkel/lib/python3.6/site-packages/sqlalchemy/orm/unitofwork.py\", line 556, in execute\n",
      "    uow\n"
     ]
    },
    {
     "name": "stderr",
     "output_type": "stream",
     "text": [
      "  File \"/lfs/local/0/jdunnmon/repos/anaconda3/envs/snorkel/lib/python3.6/site-packages/sqlalchemy/orm/persistence.py\", line 181, in save_obj\n",
      "    mapper, table, insert)\n",
      "  File \"/lfs/local/0/jdunnmon/repos/anaconda3/envs/snorkel/lib/python3.6/site-packages/sqlalchemy/orm/persistence.py\", line 830, in _emit_insert_statements\n",
      "    execute(statement, multiparams)\n",
      "  File \"/lfs/local/0/jdunnmon/repos/anaconda3/envs/snorkel/lib/python3.6/site-packages/sqlalchemy/engine/base.py\", line 948, in execute\n",
      "    return meth(self, multiparams, params)\n",
      "  File \"/lfs/local/0/jdunnmon/repos/anaconda3/envs/snorkel/lib/python3.6/site-packages/sqlalchemy/sql/elements.py\", line 269, in _execute_on_connection\n",
      "    return connection._execute_clauseelement(self, multiparams, params)\n",
      "  File \"/lfs/local/0/jdunnmon/repos/anaconda3/envs/snorkel/lib/python3.6/site-packages/sqlalchemy/engine/base.py\", line 1060, in _execute_clauseelement\n",
      "    compiled_sql, distilled_params\n",
      "  File \"/lfs/local/0/jdunnmon/repos/anaconda3/envs/snorkel/lib/python3.6/site-packages/sqlalchemy/engine/base.py\", line 1200, in _execute_context\n",
      "    context)\n",
      "  File \"/lfs/local/0/jdunnmon/repos/anaconda3/envs/snorkel/lib/python3.6/site-packages/sqlalchemy/engine/base.py\", line 1413, in _handle_dbapi_exception\n",
      "    exc_info\n",
      "  File \"/lfs/local/0/jdunnmon/repos/anaconda3/envs/snorkel/lib/python3.6/site-packages/sqlalchemy/util/compat.py\", line 203, in raise_from_cause\n",
      "    reraise(type(exception), exception, tb=exc_tb, cause=cause)\n",
      "  File \"/lfs/local/0/jdunnmon/repos/anaconda3/envs/snorkel/lib/python3.6/site-packages/sqlalchemy/util/compat.py\", line 186, in reraise\n",
      "    raise value.with_traceback(tb)\n",
      "  File \"/lfs/local/0/jdunnmon/repos/anaconda3/envs/snorkel/lib/python3.6/site-packages/sqlalchemy/engine/base.py\", line 1170, in _execute_context\n",
      "    context)\n",
      "  File \"/lfs/local/0/jdunnmon/repos/anaconda3/envs/snorkel/lib/python3.6/site-packages/sqlalchemy/dialects/postgresql/psycopg2.py\", line 683, in do_executemany\n",
      "    cursor.executemany(statement, parameters)\n",
      "sqlalchemy.exc.IntegrityError: (psycopg2.IntegrityError) duplicate key value violates unique constraint \"location_location_id_key\"\n",
      "DETAIL:  Key (location_id)=(239331) already exists.\n",
      " [SQL: 'INSERT INTO location (id, location_id, location_cid) VALUES (%(id)s, %(location_id)s, %(location_cid)s)'] [parameters: ({'id': 66450, 'location_id': 239249, 'location_cid': None}, {'id': 66461, 'location_id': 239250, 'location_cid': None}, {'id': 66473, 'location_id': 239255, 'location_cid': None}, {'id': 66490, 'location_id': 239263, 'location_cid': None}, {'id': 66507, 'location_id': 239270, 'location_cid': None}, {'id': 66524, 'location_id': 239265, 'location_cid': None}, {'id': 66536, 'location_id': 239274, 'location_cid': None}, {'id': 66552, 'location_id': 239300, 'location_cid': None}  ... displaying 10 of 5758 total bound parameter sets ...  {'id': 158149, 'location_id': 330132, 'location_cid': None}, {'id': 158164, 'location_id': 330144, 'location_cid': None})] (Background on this error at: http://sqlalche.me/e/gkpj)\n",
      "Process CandidateExtractorUDF-23:\n",
      "Traceback (most recent call last):\n",
      "  File \"/lfs/local/0/jdunnmon/repos/anaconda3/envs/snorkel/lib/python3.6/site-packages/sqlalchemy/engine/base.py\", line 1170, in _execute_context\n",
      "    context)\n",
      "  File \"/lfs/local/0/jdunnmon/repos/anaconda3/envs/snorkel/lib/python3.6/site-packages/sqlalchemy/dialects/postgresql/psycopg2.py\", line 683, in do_executemany\n",
      "    cursor.executemany(statement, parameters)\n",
      "psycopg2.IntegrityError: duplicate key value violates unique constraint \"location_location_id_key\"\n",
      "DETAIL:  Key (location_id)=(239671) already exists.\n",
      "\n",
      "\n",
      "The above exception was the direct cause of the following exception:\n",
      "\n",
      "Traceback (most recent call last):\n",
      "  File \"/lfs/local/0/jdunnmon/repos/anaconda3/envs/snorkel/lib/python3.6/multiprocessing/process.py\", line 258, in _bootstrap\n",
      "    self.run()\n",
      "  File \"/lfs/raiders5/0/jdunnmon/repos/snorkel/snorkel/udf.py\", line 170, in run\n",
      "    self.session.commit()\n",
      "  File \"/lfs/local/0/jdunnmon/repos/anaconda3/envs/snorkel/lib/python3.6/site-packages/sqlalchemy/orm/session.py\", line 943, in commit\n",
      "    self.transaction.commit()\n",
      "  File \"/lfs/local/0/jdunnmon/repos/anaconda3/envs/snorkel/lib/python3.6/site-packages/sqlalchemy/orm/session.py\", line 467, in commit\n",
      "    self._prepare_impl()\n",
      "  File \"/lfs/local/0/jdunnmon/repos/anaconda3/envs/snorkel/lib/python3.6/site-packages/sqlalchemy/orm/session.py\", line 447, in _prepare_impl\n",
      "    self.session.flush()\n",
      "  File \"/lfs/local/0/jdunnmon/repos/anaconda3/envs/snorkel/lib/python3.6/site-packages/sqlalchemy/orm/session.py\", line 2254, in flush\n",
      "    self._flush(objects)\n",
      "  File \"/lfs/local/0/jdunnmon/repos/anaconda3/envs/snorkel/lib/python3.6/site-packages/sqlalchemy/orm/session.py\", line 2380, in _flush\n",
      "    transaction.rollback(_capture_exception=True)\n",
      "  File \"/lfs/local/0/jdunnmon/repos/anaconda3/envs/snorkel/lib/python3.6/site-packages/sqlalchemy/util/langhelpers.py\", line 66, in __exit__\n",
      "    compat.reraise(exc_type, exc_value, exc_tb)\n",
      "  File \"/lfs/local/0/jdunnmon/repos/anaconda3/envs/snorkel/lib/python3.6/site-packages/sqlalchemy/util/compat.py\", line 187, in reraise\n",
      "    raise value\n",
      "  File \"/lfs/local/0/jdunnmon/repos/anaconda3/envs/snorkel/lib/python3.6/site-packages/sqlalchemy/orm/session.py\", line 2344, in _flush\n",
      "    flush_context.execute()\n",
      "  File \"/lfs/local/0/jdunnmon/repos/anaconda3/envs/snorkel/lib/python3.6/site-packages/sqlalchemy/orm/unitofwork.py\", line 391, in execute\n",
      "    rec.execute(self)\n",
      "  File \"/lfs/local/0/jdunnmon/repos/anaconda3/envs/snorkel/lib/python3.6/site-packages/sqlalchemy/orm/unitofwork.py\", line 556, in execute\n",
      "    uow\n",
      "  File \"/lfs/local/0/jdunnmon/repos/anaconda3/envs/snorkel/lib/python3.6/site-packages/sqlalchemy/orm/persistence.py\", line 181, in save_obj\n",
      "    mapper, table, insert)\n",
      "  File \"/lfs/local/0/jdunnmon/repos/anaconda3/envs/snorkel/lib/python3.6/site-packages/sqlalchemy/orm/persistence.py\", line 830, in _emit_insert_statements\n",
      "    execute(statement, multiparams)\n",
      "  File \"/lfs/local/0/jdunnmon/repos/anaconda3/envs/snorkel/lib/python3.6/site-packages/sqlalchemy/engine/base.py\", line 948, in execute\n",
      "    return meth(self, multiparams, params)\n",
      "  File \"/lfs/local/0/jdunnmon/repos/anaconda3/envs/snorkel/lib/python3.6/site-packages/sqlalchemy/sql/elements.py\", line 269, in _execute_on_connection\n",
      "    return connection._execute_clauseelement(self, multiparams, params)\n",
      "  File \"/lfs/local/0/jdunnmon/repos/anaconda3/envs/snorkel/lib/python3.6/site-packages/sqlalchemy/engine/base.py\", line 1060, in _execute_clauseelement\n",
      "    compiled_sql, distilled_params\n",
      "  File \"/lfs/local/0/jdunnmon/repos/anaconda3/envs/snorkel/lib/python3.6/site-packages/sqlalchemy/engine/base.py\", line 1200, in _execute_context\n",
      "    context)\n",
      "  File \"/lfs/local/0/jdunnmon/repos/anaconda3/envs/snorkel/lib/python3.6/site-packages/sqlalchemy/engine/base.py\", line 1413, in _handle_dbapi_exception\n",
      "    exc_info\n",
      "  File \"/lfs/local/0/jdunnmon/repos/anaconda3/envs/snorkel/lib/python3.6/site-packages/sqlalchemy/util/compat.py\", line 203, in raise_from_cause\n",
      "    reraise(type(exception), exception, tb=exc_tb, cause=cause)\n",
      "  File \"/lfs/local/0/jdunnmon/repos/anaconda3/envs/snorkel/lib/python3.6/site-packages/sqlalchemy/util/compat.py\", line 186, in reraise\n",
      "    raise value.with_traceback(tb)\n",
      "  File \"/lfs/local/0/jdunnmon/repos/anaconda3/envs/snorkel/lib/python3.6/site-packages/sqlalchemy/engine/base.py\", line 1170, in _execute_context\n",
      "    context)\n",
      "  File \"/lfs/local/0/jdunnmon/repos/anaconda3/envs/snorkel/lib/python3.6/site-packages/sqlalchemy/dialects/postgresql/psycopg2.py\", line 683, in do_executemany\n",
      "    cursor.executemany(statement, parameters)\n",
      "sqlalchemy.exc.IntegrityError: (psycopg2.IntegrityError) duplicate key value violates unique constraint \"location_location_id_key\"\n",
      "DETAIL:  Key (location_id)=(239671) already exists.\n",
      " [SQL: 'INSERT INTO location (id, location_id, location_cid) VALUES (%(id)s, %(location_id)s, %(location_cid)s)'] [parameters: ({'id': 66445, 'location_id': 239287, 'location_cid': None}, {'id': 66452, 'location_id': 239289, 'location_cid': None}, {'id': 66465, 'location_id': 239305, 'location_cid': None}, {'id': 66480, 'location_id': 239321, 'location_cid': None}, {'id': 66495, 'location_id': 239329, 'location_cid': None}, {'id': 66517, 'location_id': 239333, 'location_cid': None}, {'id': 66527, 'location_id': 239324, 'location_cid': None}, {'id': 66544, 'location_id': 239326, 'location_cid': None}  ... displaying 10 of 5776 total bound parameter sets ...  {'id': 158347, 'location_id': 330130, 'location_cid': None}, {'id': 158355, 'location_id': 330134, 'location_cid': None})] (Background on this error at: http://sqlalche.me/e/gkpj)\n"
     ]
    },
    {
     "name": "stderr",
     "output_type": "stream",
     "text": [
      "Process CandidateExtractorUDF-27:\n",
      "Traceback (most recent call last):\n",
      "  File \"/lfs/local/0/jdunnmon/repos/anaconda3/envs/snorkel/lib/python3.6/site-packages/sqlalchemy/engine/base.py\", line 1170, in _execute_context\n",
      "    context)\n",
      "  File \"/lfs/local/0/jdunnmon/repos/anaconda3/envs/snorkel/lib/python3.6/site-packages/sqlalchemy/dialects/postgresql/psycopg2.py\", line 683, in do_executemany\n",
      "    cursor.executemany(statement, parameters)\n",
      "psycopg2.IntegrityError: duplicate key value violates unique constraint \"location_location_id_key\"\n",
      "DETAIL:  Key (location_id)=(239654) already exists.\n",
      "\n",
      "\n",
      "The above exception was the direct cause of the following exception:\n",
      "\n",
      "Traceback (most recent call last):\n",
      "  File \"/lfs/local/0/jdunnmon/repos/anaconda3/envs/snorkel/lib/python3.6/multiprocessing/process.py\", line 258, in _bootstrap\n",
      "    self.run()\n",
      "  File \"/lfs/raiders5/0/jdunnmon/repos/snorkel/snorkel/udf.py\", line 170, in run\n",
      "    self.session.commit()\n",
      "  File \"/lfs/local/0/jdunnmon/repos/anaconda3/envs/snorkel/lib/python3.6/site-packages/sqlalchemy/orm/session.py\", line 943, in commit\n",
      "    self.transaction.commit()\n",
      "  File \"/lfs/local/0/jdunnmon/repos/anaconda3/envs/snorkel/lib/python3.6/site-packages/sqlalchemy/orm/session.py\", line 467, in commit\n",
      "    self._prepare_impl()\n",
      "  File \"/lfs/local/0/jdunnmon/repos/anaconda3/envs/snorkel/lib/python3.6/site-packages/sqlalchemy/orm/session.py\", line 447, in _prepare_impl\n",
      "    self.session.flush()\n",
      "  File \"/lfs/local/0/jdunnmon/repos/anaconda3/envs/snorkel/lib/python3.6/site-packages/sqlalchemy/orm/session.py\", line 2254, in flush\n",
      "    self._flush(objects)\n",
      "  File \"/lfs/local/0/jdunnmon/repos/anaconda3/envs/snorkel/lib/python3.6/site-packages/sqlalchemy/orm/session.py\", line 2380, in _flush\n",
      "    transaction.rollback(_capture_exception=True)\n",
      "  File \"/lfs/local/0/jdunnmon/repos/anaconda3/envs/snorkel/lib/python3.6/site-packages/sqlalchemy/util/langhelpers.py\", line 66, in __exit__\n",
      "    compat.reraise(exc_type, exc_value, exc_tb)\n",
      "  File \"/lfs/local/0/jdunnmon/repos/anaconda3/envs/snorkel/lib/python3.6/site-packages/sqlalchemy/util/compat.py\", line 187, in reraise\n",
      "    raise value\n",
      "  File \"/lfs/local/0/jdunnmon/repos/anaconda3/envs/snorkel/lib/python3.6/site-packages/sqlalchemy/orm/session.py\", line 2344, in _flush\n",
      "    flush_context.execute()\n",
      "  File \"/lfs/local/0/jdunnmon/repos/anaconda3/envs/snorkel/lib/python3.6/site-packages/sqlalchemy/orm/unitofwork.py\", line 391, in execute\n",
      "    rec.execute(self)\n",
      "  File \"/lfs/local/0/jdunnmon/repos/anaconda3/envs/snorkel/lib/python3.6/site-packages/sqlalchemy/orm/unitofwork.py\", line 556, in execute\n",
      "    uow\n",
      "  File \"/lfs/local/0/jdunnmon/repos/anaconda3/envs/snorkel/lib/python3.6/site-packages/sqlalchemy/orm/persistence.py\", line 181, in save_obj\n",
      "    mapper, table, insert)\n",
      "  File \"/lfs/local/0/jdunnmon/repos/anaconda3/envs/snorkel/lib/python3.6/site-packages/sqlalchemy/orm/persistence.py\", line 830, in _emit_insert_statements\n",
      "    execute(statement, multiparams)\n",
      "  File \"/lfs/local/0/jdunnmon/repos/anaconda3/envs/snorkel/lib/python3.6/site-packages/sqlalchemy/engine/base.py\", line 948, in execute\n",
      "    return meth(self, multiparams, params)\n",
      "  File \"/lfs/local/0/jdunnmon/repos/anaconda3/envs/snorkel/lib/python3.6/site-packages/sqlalchemy/sql/elements.py\", line 269, in _execute_on_connection\n",
      "    return connection._execute_clauseelement(self, multiparams, params)\n",
      "  File \"/lfs/local/0/jdunnmon/repos/anaconda3/envs/snorkel/lib/python3.6/site-packages/sqlalchemy/engine/base.py\", line 1060, in _execute_clauseelement\n",
      "    compiled_sql, distilled_params\n",
      "  File \"/lfs/local/0/jdunnmon/repos/anaconda3/envs/snorkel/lib/python3.6/site-packages/sqlalchemy/engine/base.py\", line 1200, in _execute_context\n",
      "    context)\n",
      "  File \"/lfs/local/0/jdunnmon/repos/anaconda3/envs/snorkel/lib/python3.6/site-packages/sqlalchemy/engine/base.py\", line 1413, in _handle_dbapi_exception\n",
      "    exc_info\n",
      "  File \"/lfs/local/0/jdunnmon/repos/anaconda3/envs/snorkel/lib/python3.6/site-packages/sqlalchemy/util/compat.py\", line 203, in raise_from_cause\n",
      "    reraise(type(exception), exception, tb=exc_tb, cause=cause)\n",
      "  File \"/lfs/local/0/jdunnmon/repos/anaconda3/envs/snorkel/lib/python3.6/site-packages/sqlalchemy/util/compat.py\", line 186, in reraise\n",
      "    raise value.with_traceback(tb)\n",
      "  File \"/lfs/local/0/jdunnmon/repos/anaconda3/envs/snorkel/lib/python3.6/site-packages/sqlalchemy/engine/base.py\", line 1170, in _execute_context\n",
      "    context)\n",
      "  File \"/lfs/local/0/jdunnmon/repos/anaconda3/envs/snorkel/lib/python3.6/site-packages/sqlalchemy/dialects/postgresql/psycopg2.py\", line 683, in do_executemany\n",
      "    cursor.executemany(statement, parameters)\n",
      "sqlalchemy.exc.IntegrityError: (psycopg2.IntegrityError) duplicate key value violates unique constraint \"location_location_id_key\"\n",
      "DETAIL:  Key (location_id)=(239654) already exists.\n",
      " [SQL: 'INSERT INTO location (id, location_id, location_cid) VALUES (%(id)s, %(location_id)s, %(location_cid)s)'] [parameters: ({'id': 66457, 'location_id': 239295, 'location_cid': None}, {'id': 66470, 'location_id': 239302, 'location_cid': None}, {'id': 66484, 'location_id': 239318, 'location_cid': None}, {'id': 66500, 'location_id': 239311, 'location_cid': None}, {'id': 66516, 'location_id': 239345, 'location_cid': None}, {'id': 66526, 'location_id': 239350, 'location_cid': None}, {'id': 66548, 'location_id': 239392, 'location_cid': None}, {'id': 66563, 'location_id': 239417, 'location_cid': None}  ... displaying 10 of 5829 total bound parameter sets ...  {'id': 158686, 'location_id': 330105, 'location_cid': None}, {'id': 158689, 'location_id': 330109, 'location_cid': None})] (Background on this error at: http://sqlalche.me/e/gkpj)\n",
      "Process CandidateExtractorUDF-19:\n",
      "Traceback (most recent call last):\n",
      "  File \"/lfs/local/0/jdunnmon/repos/anaconda3/envs/snorkel/lib/python3.6/site-packages/sqlalchemy/engine/base.py\", line 1170, in _execute_context\n",
      "    context)\n",
      "  File \"/lfs/local/0/jdunnmon/repos/anaconda3/envs/snorkel/lib/python3.6/site-packages/sqlalchemy/dialects/postgresql/psycopg2.py\", line 683, in do_executemany\n",
      "    cursor.executemany(statement, parameters)\n",
      "psycopg2.IntegrityError: duplicate key value violates unique constraint \"location_location_id_key\"\n",
      "DETAIL:  Key (location_id)=(240419) already exists.\n",
      "\n",
      "\n",
      "The above exception was the direct cause of the following exception:\n",
      "\n",
      "Traceback (most recent call last):\n",
      "  File \"/lfs/local/0/jdunnmon/repos/anaconda3/envs/snorkel/lib/python3.6/multiprocessing/process.py\", line 258, in _bootstrap\n",
      "    self.run()\n",
      "  File \"/lfs/raiders5/0/jdunnmon/repos/snorkel/snorkel/udf.py\", line 170, in run\n",
      "    self.session.commit()\n",
      "  File \"/lfs/local/0/jdunnmon/repos/anaconda3/envs/snorkel/lib/python3.6/site-packages/sqlalchemy/orm/session.py\", line 943, in commit\n",
      "    self.transaction.commit()\n",
      "  File \"/lfs/local/0/jdunnmon/repos/anaconda3/envs/snorkel/lib/python3.6/site-packages/sqlalchemy/orm/session.py\", line 467, in commit\n",
      "    self._prepare_impl()\n",
      "  File \"/lfs/local/0/jdunnmon/repos/anaconda3/envs/snorkel/lib/python3.6/site-packages/sqlalchemy/orm/session.py\", line 447, in _prepare_impl\n",
      "    self.session.flush()\n",
      "  File \"/lfs/local/0/jdunnmon/repos/anaconda3/envs/snorkel/lib/python3.6/site-packages/sqlalchemy/orm/session.py\", line 2254, in flush\n",
      "    self._flush(objects)\n",
      "  File \"/lfs/local/0/jdunnmon/repos/anaconda3/envs/snorkel/lib/python3.6/site-packages/sqlalchemy/orm/session.py\", line 2380, in _flush\n",
      "    transaction.rollback(_capture_exception=True)\n",
      "  File \"/lfs/local/0/jdunnmon/repos/anaconda3/envs/snorkel/lib/python3.6/site-packages/sqlalchemy/util/langhelpers.py\", line 66, in __exit__\n",
      "    compat.reraise(exc_type, exc_value, exc_tb)\n",
      "  File \"/lfs/local/0/jdunnmon/repos/anaconda3/envs/snorkel/lib/python3.6/site-packages/sqlalchemy/util/compat.py\", line 187, in reraise\n",
      "    raise value\n",
      "  File \"/lfs/local/0/jdunnmon/repos/anaconda3/envs/snorkel/lib/python3.6/site-packages/sqlalchemy/orm/session.py\", line 2344, in _flush\n",
      "    flush_context.execute()\n",
      "  File \"/lfs/local/0/jdunnmon/repos/anaconda3/envs/snorkel/lib/python3.6/site-packages/sqlalchemy/orm/unitofwork.py\", line 391, in execute\n",
      "    rec.execute(self)\n",
      "  File \"/lfs/local/0/jdunnmon/repos/anaconda3/envs/snorkel/lib/python3.6/site-packages/sqlalchemy/orm/unitofwork.py\", line 556, in execute\n",
      "    uow\n"
     ]
    },
    {
     "name": "stderr",
     "output_type": "stream",
     "text": [
      "  File \"/lfs/local/0/jdunnmon/repos/anaconda3/envs/snorkel/lib/python3.6/site-packages/sqlalchemy/orm/persistence.py\", line 181, in save_obj\n",
      "    mapper, table, insert)\n",
      "  File \"/lfs/local/0/jdunnmon/repos/anaconda3/envs/snorkel/lib/python3.6/site-packages/sqlalchemy/orm/persistence.py\", line 830, in _emit_insert_statements\n",
      "    execute(statement, multiparams)\n",
      "  File \"/lfs/local/0/jdunnmon/repos/anaconda3/envs/snorkel/lib/python3.6/site-packages/sqlalchemy/engine/base.py\", line 948, in execute\n",
      "    return meth(self, multiparams, params)\n",
      "  File \"/lfs/local/0/jdunnmon/repos/anaconda3/envs/snorkel/lib/python3.6/site-packages/sqlalchemy/sql/elements.py\", line 269, in _execute_on_connection\n",
      "    return connection._execute_clauseelement(self, multiparams, params)\n",
      "  File \"/lfs/local/0/jdunnmon/repos/anaconda3/envs/snorkel/lib/python3.6/site-packages/sqlalchemy/engine/base.py\", line 1060, in _execute_clauseelement\n",
      "    compiled_sql, distilled_params\n",
      "  File \"/lfs/local/0/jdunnmon/repos/anaconda3/envs/snorkel/lib/python3.6/site-packages/sqlalchemy/engine/base.py\", line 1200, in _execute_context\n",
      "    context)\n",
      "  File \"/lfs/local/0/jdunnmon/repos/anaconda3/envs/snorkel/lib/python3.6/site-packages/sqlalchemy/engine/base.py\", line 1413, in _handle_dbapi_exception\n",
      "    exc_info\n",
      "  File \"/lfs/local/0/jdunnmon/repos/anaconda3/envs/snorkel/lib/python3.6/site-packages/sqlalchemy/util/compat.py\", line 203, in raise_from_cause\n",
      "    reraise(type(exception), exception, tb=exc_tb, cause=cause)\n",
      "  File \"/lfs/local/0/jdunnmon/repos/anaconda3/envs/snorkel/lib/python3.6/site-packages/sqlalchemy/util/compat.py\", line 186, in reraise\n",
      "    raise value.with_traceback(tb)\n",
      "  File \"/lfs/local/0/jdunnmon/repos/anaconda3/envs/snorkel/lib/python3.6/site-packages/sqlalchemy/engine/base.py\", line 1170, in _execute_context\n",
      "    context)\n",
      "  File \"/lfs/local/0/jdunnmon/repos/anaconda3/envs/snorkel/lib/python3.6/site-packages/sqlalchemy/dialects/postgresql/psycopg2.py\", line 683, in do_executemany\n",
      "    cursor.executemany(statement, parameters)\n",
      "sqlalchemy.exc.IntegrityError: (psycopg2.IntegrityError) duplicate key value violates unique constraint \"location_location_id_key\"\n",
      "DETAIL:  Key (location_id)=(240419) already exists.\n",
      " [SQL: 'INSERT INTO location (id, location_id, location_cid) VALUES (%(id)s, %(location_id)s, %(location_cid)s)'] [parameters: ({'id': 66446, 'location_id': 239252, 'location_cid': None}, {'id': 66454, 'location_id': 239257, 'location_cid': None}, {'id': 66464, 'location_id': 239258, 'location_cid': None}, {'id': 66479, 'location_id': 239256, 'location_cid': None}, {'id': 66497, 'location_id': 239266, 'location_cid': None}, {'id': 66511, 'location_id': 239273, 'location_cid': None}, {'id': 66532, 'location_id': 239262, 'location_cid': None}, {'id': 66542, 'location_id': 239269, 'location_cid': None}  ... displaying 10 of 5775 total bound parameter sets ...  {'id': 158327, 'location_id': 330092, 'location_cid': None}, {'id': 158338, 'location_id': 330142, 'location_cid': None})] (Background on this error at: http://sqlalche.me/e/gkpj)\n",
      "Process CandidateExtractorUDF-17:\n",
      "Traceback (most recent call last):\n",
      "  File \"/lfs/local/0/jdunnmon/repos/anaconda3/envs/snorkel/lib/python3.6/site-packages/sqlalchemy/engine/base.py\", line 1170, in _execute_context\n",
      "    context)\n",
      "  File \"/lfs/local/0/jdunnmon/repos/anaconda3/envs/snorkel/lib/python3.6/site-packages/sqlalchemy/dialects/postgresql/psycopg2.py\", line 683, in do_executemany\n",
      "    cursor.executemany(statement, parameters)\n",
      "psycopg2.IntegrityError: duplicate key value violates unique constraint \"location_location_id_key\"\n",
      "DETAIL:  Key (location_id)=(239977) already exists.\n",
      "\n",
      "\n",
      "The above exception was the direct cause of the following exception:\n",
      "\n",
      "Traceback (most recent call last):\n",
      "  File \"/lfs/local/0/jdunnmon/repos/anaconda3/envs/snorkel/lib/python3.6/multiprocessing/process.py\", line 258, in _bootstrap\n",
      "    self.run()\n",
      "  File \"/lfs/raiders5/0/jdunnmon/repos/snorkel/snorkel/udf.py\", line 170, in run\n",
      "    self.session.commit()\n",
      "  File \"/lfs/local/0/jdunnmon/repos/anaconda3/envs/snorkel/lib/python3.6/site-packages/sqlalchemy/orm/session.py\", line 943, in commit\n",
      "    self.transaction.commit()\n",
      "  File \"/lfs/local/0/jdunnmon/repos/anaconda3/envs/snorkel/lib/python3.6/site-packages/sqlalchemy/orm/session.py\", line 467, in commit\n",
      "    self._prepare_impl()\n",
      "  File \"/lfs/local/0/jdunnmon/repos/anaconda3/envs/snorkel/lib/python3.6/site-packages/sqlalchemy/orm/session.py\", line 447, in _prepare_impl\n",
      "    self.session.flush()\n",
      "  File \"/lfs/local/0/jdunnmon/repos/anaconda3/envs/snorkel/lib/python3.6/site-packages/sqlalchemy/orm/session.py\", line 2254, in flush\n",
      "    self._flush(objects)\n",
      "  File \"/lfs/local/0/jdunnmon/repos/anaconda3/envs/snorkel/lib/python3.6/site-packages/sqlalchemy/orm/session.py\", line 2380, in _flush\n",
      "    transaction.rollback(_capture_exception=True)\n",
      "  File \"/lfs/local/0/jdunnmon/repos/anaconda3/envs/snorkel/lib/python3.6/site-packages/sqlalchemy/util/langhelpers.py\", line 66, in __exit__\n",
      "    compat.reraise(exc_type, exc_value, exc_tb)\n",
      "  File \"/lfs/local/0/jdunnmon/repos/anaconda3/envs/snorkel/lib/python3.6/site-packages/sqlalchemy/util/compat.py\", line 187, in reraise\n",
      "    raise value\n",
      "  File \"/lfs/local/0/jdunnmon/repos/anaconda3/envs/snorkel/lib/python3.6/site-packages/sqlalchemy/orm/session.py\", line 2344, in _flush\n",
      "    flush_context.execute()\n",
      "  File \"/lfs/local/0/jdunnmon/repos/anaconda3/envs/snorkel/lib/python3.6/site-packages/sqlalchemy/orm/unitofwork.py\", line 391, in execute\n",
      "    rec.execute(self)\n",
      "  File \"/lfs/local/0/jdunnmon/repos/anaconda3/envs/snorkel/lib/python3.6/site-packages/sqlalchemy/orm/unitofwork.py\", line 556, in execute\n",
      "    uow\n",
      "  File \"/lfs/local/0/jdunnmon/repos/anaconda3/envs/snorkel/lib/python3.6/site-packages/sqlalchemy/orm/persistence.py\", line 181, in save_obj\n",
      "    mapper, table, insert)\n",
      "  File \"/lfs/local/0/jdunnmon/repos/anaconda3/envs/snorkel/lib/python3.6/site-packages/sqlalchemy/orm/persistence.py\", line 830, in _emit_insert_statements\n",
      "    execute(statement, multiparams)\n",
      "  File \"/lfs/local/0/jdunnmon/repos/anaconda3/envs/snorkel/lib/python3.6/site-packages/sqlalchemy/engine/base.py\", line 948, in execute\n",
      "    return meth(self, multiparams, params)\n",
      "  File \"/lfs/local/0/jdunnmon/repos/anaconda3/envs/snorkel/lib/python3.6/site-packages/sqlalchemy/sql/elements.py\", line 269, in _execute_on_connection\n",
      "    return connection._execute_clauseelement(self, multiparams, params)\n",
      "  File \"/lfs/local/0/jdunnmon/repos/anaconda3/envs/snorkel/lib/python3.6/site-packages/sqlalchemy/engine/base.py\", line 1060, in _execute_clauseelement\n",
      "    compiled_sql, distilled_params\n",
      "  File \"/lfs/local/0/jdunnmon/repos/anaconda3/envs/snorkel/lib/python3.6/site-packages/sqlalchemy/engine/base.py\", line 1200, in _execute_context\n",
      "    context)\n",
      "  File \"/lfs/local/0/jdunnmon/repos/anaconda3/envs/snorkel/lib/python3.6/site-packages/sqlalchemy/engine/base.py\", line 1413, in _handle_dbapi_exception\n",
      "    exc_info\n",
      "  File \"/lfs/local/0/jdunnmon/repos/anaconda3/envs/snorkel/lib/python3.6/site-packages/sqlalchemy/util/compat.py\", line 203, in raise_from_cause\n",
      "    reraise(type(exception), exception, tb=exc_tb, cause=cause)\n",
      "  File \"/lfs/local/0/jdunnmon/repos/anaconda3/envs/snorkel/lib/python3.6/site-packages/sqlalchemy/util/compat.py\", line 186, in reraise\n",
      "    raise value.with_traceback(tb)\n",
      "  File \"/lfs/local/0/jdunnmon/repos/anaconda3/envs/snorkel/lib/python3.6/site-packages/sqlalchemy/engine/base.py\", line 1170, in _execute_context\n",
      "    context)\n",
      "  File \"/lfs/local/0/jdunnmon/repos/anaconda3/envs/snorkel/lib/python3.6/site-packages/sqlalchemy/dialects/postgresql/psycopg2.py\", line 683, in do_executemany\n",
      "    cursor.executemany(statement, parameters)\n",
      "sqlalchemy.exc.IntegrityError: (psycopg2.IntegrityError) duplicate key value violates unique constraint \"location_location_id_key\"\n",
      "DETAIL:  Key (location_id)=(239977) already exists.\n",
      " [SQL: 'INSERT INTO location (id, location_id, location_cid) VALUES (%(id)s, %(location_id)s, %(location_cid)s)'] [parameters: ({'id': 66449, 'location_id': 239245, 'location_cid': None}, {'id': 66460, 'location_id': 239246, 'location_cid': None}, {'id': 66474, 'location_id': 239247, 'location_cid': None}, {'id': 66488, 'location_id': 239248, 'location_cid': None}, {'id': 66506, 'location_id': 239251, 'location_cid': None}, {'id': 66521, 'location_id': 239253, 'location_cid': None}, {'id': 66537, 'location_id': 239272, 'location_cid': None}, {'id': 66553, 'location_id': 239268, 'location_cid': None}  ... displaying 10 of 5812 total bound parameter sets ...  {'id': 158618, 'location_id': 330123, 'location_cid': None}, {'id': 158627, 'location_id': 330119, 'location_cid': None})] (Background on this error at: http://sqlalche.me/e/gkpj)\n"
     ]
    },
    {
     "name": "stderr",
     "output_type": "stream",
     "text": [
      "Process CandidateExtractorUDF-26:\n",
      "Traceback (most recent call last):\n",
      "  File \"/lfs/local/0/jdunnmon/repos/anaconda3/envs/snorkel/lib/python3.6/site-packages/sqlalchemy/engine/base.py\", line 1170, in _execute_context\n",
      "    context)\n",
      "  File \"/lfs/local/0/jdunnmon/repos/anaconda3/envs/snorkel/lib/python3.6/site-packages/sqlalchemy/dialects/postgresql/psycopg2.py\", line 683, in do_executemany\n",
      "    cursor.executemany(statement, parameters)\n",
      "psycopg2.IntegrityError: duplicate key value violates unique constraint \"location_location_id_key\"\n",
      "DETAIL:  Key (location_id)=(241384) already exists.\n",
      "\n",
      "\n",
      "The above exception was the direct cause of the following exception:\n",
      "\n",
      "Traceback (most recent call last):\n",
      "  File \"/lfs/local/0/jdunnmon/repos/anaconda3/envs/snorkel/lib/python3.6/multiprocessing/process.py\", line 258, in _bootstrap\n",
      "    self.run()\n",
      "  File \"/lfs/raiders5/0/jdunnmon/repos/snorkel/snorkel/udf.py\", line 170, in run\n",
      "    self.session.commit()\n",
      "  File \"/lfs/local/0/jdunnmon/repos/anaconda3/envs/snorkel/lib/python3.6/site-packages/sqlalchemy/orm/session.py\", line 943, in commit\n",
      "    self.transaction.commit()\n",
      "  File \"/lfs/local/0/jdunnmon/repos/anaconda3/envs/snorkel/lib/python3.6/site-packages/sqlalchemy/orm/session.py\", line 467, in commit\n",
      "    self._prepare_impl()\n",
      "  File \"/lfs/local/0/jdunnmon/repos/anaconda3/envs/snorkel/lib/python3.6/site-packages/sqlalchemy/orm/session.py\", line 447, in _prepare_impl\n",
      "    self.session.flush()\n",
      "  File \"/lfs/local/0/jdunnmon/repos/anaconda3/envs/snorkel/lib/python3.6/site-packages/sqlalchemy/orm/session.py\", line 2254, in flush\n",
      "    self._flush(objects)\n",
      "  File \"/lfs/local/0/jdunnmon/repos/anaconda3/envs/snorkel/lib/python3.6/site-packages/sqlalchemy/orm/session.py\", line 2380, in _flush\n",
      "    transaction.rollback(_capture_exception=True)\n",
      "  File \"/lfs/local/0/jdunnmon/repos/anaconda3/envs/snorkel/lib/python3.6/site-packages/sqlalchemy/util/langhelpers.py\", line 66, in __exit__\n",
      "    compat.reraise(exc_type, exc_value, exc_tb)\n",
      "  File \"/lfs/local/0/jdunnmon/repos/anaconda3/envs/snorkel/lib/python3.6/site-packages/sqlalchemy/util/compat.py\", line 187, in reraise\n",
      "    raise value\n",
      "  File \"/lfs/local/0/jdunnmon/repos/anaconda3/envs/snorkel/lib/python3.6/site-packages/sqlalchemy/orm/session.py\", line 2344, in _flush\n",
      "    flush_context.execute()\n",
      "  File \"/lfs/local/0/jdunnmon/repos/anaconda3/envs/snorkel/lib/python3.6/site-packages/sqlalchemy/orm/unitofwork.py\", line 391, in execute\n",
      "    rec.execute(self)\n",
      "  File \"/lfs/local/0/jdunnmon/repos/anaconda3/envs/snorkel/lib/python3.6/site-packages/sqlalchemy/orm/unitofwork.py\", line 556, in execute\n",
      "    uow\n",
      "  File \"/lfs/local/0/jdunnmon/repos/anaconda3/envs/snorkel/lib/python3.6/site-packages/sqlalchemy/orm/persistence.py\", line 181, in save_obj\n",
      "    mapper, table, insert)\n",
      "  File \"/lfs/local/0/jdunnmon/repos/anaconda3/envs/snorkel/lib/python3.6/site-packages/sqlalchemy/orm/persistence.py\", line 830, in _emit_insert_statements\n",
      "    execute(statement, multiparams)\n",
      "  File \"/lfs/local/0/jdunnmon/repos/anaconda3/envs/snorkel/lib/python3.6/site-packages/sqlalchemy/engine/base.py\", line 948, in execute\n",
      "    return meth(self, multiparams, params)\n",
      "  File \"/lfs/local/0/jdunnmon/repos/anaconda3/envs/snorkel/lib/python3.6/site-packages/sqlalchemy/sql/elements.py\", line 269, in _execute_on_connection\n",
      "    return connection._execute_clauseelement(self, multiparams, params)\n",
      "  File \"/lfs/local/0/jdunnmon/repos/anaconda3/envs/snorkel/lib/python3.6/site-packages/sqlalchemy/engine/base.py\", line 1060, in _execute_clauseelement\n",
      "    compiled_sql, distilled_params\n",
      "  File \"/lfs/local/0/jdunnmon/repos/anaconda3/envs/snorkel/lib/python3.6/site-packages/sqlalchemy/engine/base.py\", line 1200, in _execute_context\n",
      "    context)\n",
      "  File \"/lfs/local/0/jdunnmon/repos/anaconda3/envs/snorkel/lib/python3.6/site-packages/sqlalchemy/engine/base.py\", line 1413, in _handle_dbapi_exception\n",
      "    exc_info\n",
      "  File \"/lfs/local/0/jdunnmon/repos/anaconda3/envs/snorkel/lib/python3.6/site-packages/sqlalchemy/util/compat.py\", line 203, in raise_from_cause\n",
      "    reraise(type(exception), exception, tb=exc_tb, cause=cause)\n",
      "  File \"/lfs/local/0/jdunnmon/repos/anaconda3/envs/snorkel/lib/python3.6/site-packages/sqlalchemy/util/compat.py\", line 186, in reraise\n",
      "    raise value.with_traceback(tb)\n",
      "  File \"/lfs/local/0/jdunnmon/repos/anaconda3/envs/snorkel/lib/python3.6/site-packages/sqlalchemy/engine/base.py\", line 1170, in _execute_context\n",
      "    context)\n",
      "  File \"/lfs/local/0/jdunnmon/repos/anaconda3/envs/snorkel/lib/python3.6/site-packages/sqlalchemy/dialects/postgresql/psycopg2.py\", line 683, in do_executemany\n",
      "    cursor.executemany(statement, parameters)\n",
      "sqlalchemy.exc.IntegrityError: (psycopg2.IntegrityError) duplicate key value violates unique constraint \"location_location_id_key\"\n",
      "DETAIL:  Key (location_id)=(241384) already exists.\n",
      " [SQL: 'INSERT INTO location (id, location_id, location_cid) VALUES (%(id)s, %(location_id)s, %(location_cid)s)'] [parameters: ({'id': 66472, 'location_id': 239301, 'location_cid': None}, {'id': 66487, 'location_id': 239363, 'location_cid': None}, {'id': 66499, 'location_id': 239367, 'location_cid': None}, {'id': 66512, 'location_id': 239371, 'location_cid': None}, {'id': 66531, 'location_id': 239387, 'location_cid': None}, {'id': 66543, 'location_id': 239381, 'location_cid': None}, {'id': 66564, 'location_id': 239408, 'location_cid': None}, {'id': 66583, 'location_id': 239419, 'location_cid': None}  ... displaying 10 of 5752 total bound parameter sets ...  {'id': 158106, 'location_id': 330123, 'location_cid': None}, {'id': 158118, 'location_id': 330141, 'location_cid': None})] (Background on this error at: http://sqlalche.me/e/gkpj)\n",
      "Process CandidateExtractorUDF-21:\n",
      "Traceback (most recent call last):\n",
      "  File \"/lfs/local/0/jdunnmon/repos/anaconda3/envs/snorkel/lib/python3.6/site-packages/sqlalchemy/engine/base.py\", line 1170, in _execute_context\n",
      "    context)\n",
      "  File \"/lfs/local/0/jdunnmon/repos/anaconda3/envs/snorkel/lib/python3.6/site-packages/sqlalchemy/dialects/postgresql/psycopg2.py\", line 683, in do_executemany\n",
      "    cursor.executemany(statement, parameters)\n",
      "psycopg2.IntegrityError: duplicate key value violates unique constraint \"location_location_id_key\"\n",
      "DETAIL:  Key (location_id)=(241538) already exists.\n",
      "\n",
      "\n",
      "The above exception was the direct cause of the following exception:\n",
      "\n",
      "Traceback (most recent call last):\n",
      "  File \"/lfs/local/0/jdunnmon/repos/anaconda3/envs/snorkel/lib/python3.6/multiprocessing/process.py\", line 258, in _bootstrap\n",
      "    self.run()\n",
      "  File \"/lfs/raiders5/0/jdunnmon/repos/snorkel/snorkel/udf.py\", line 170, in run\n",
      "    self.session.commit()\n",
      "  File \"/lfs/local/0/jdunnmon/repos/anaconda3/envs/snorkel/lib/python3.6/site-packages/sqlalchemy/orm/session.py\", line 943, in commit\n",
      "    self.transaction.commit()\n",
      "  File \"/lfs/local/0/jdunnmon/repos/anaconda3/envs/snorkel/lib/python3.6/site-packages/sqlalchemy/orm/session.py\", line 467, in commit\n",
      "    self._prepare_impl()\n",
      "  File \"/lfs/local/0/jdunnmon/repos/anaconda3/envs/snorkel/lib/python3.6/site-packages/sqlalchemy/orm/session.py\", line 447, in _prepare_impl\n",
      "    self.session.flush()\n",
      "  File \"/lfs/local/0/jdunnmon/repos/anaconda3/envs/snorkel/lib/python3.6/site-packages/sqlalchemy/orm/session.py\", line 2254, in flush\n",
      "    self._flush(objects)\n",
      "  File \"/lfs/local/0/jdunnmon/repos/anaconda3/envs/snorkel/lib/python3.6/site-packages/sqlalchemy/orm/session.py\", line 2380, in _flush\n",
      "    transaction.rollback(_capture_exception=True)\n",
      "  File \"/lfs/local/0/jdunnmon/repos/anaconda3/envs/snorkel/lib/python3.6/site-packages/sqlalchemy/util/langhelpers.py\", line 66, in __exit__\n",
      "    compat.reraise(exc_type, exc_value, exc_tb)\n",
      "  File \"/lfs/local/0/jdunnmon/repos/anaconda3/envs/snorkel/lib/python3.6/site-packages/sqlalchemy/util/compat.py\", line 187, in reraise\n",
      "    raise value\n",
      "  File \"/lfs/local/0/jdunnmon/repos/anaconda3/envs/snorkel/lib/python3.6/site-packages/sqlalchemy/orm/session.py\", line 2344, in _flush\n",
      "    flush_context.execute()\n",
      "  File \"/lfs/local/0/jdunnmon/repos/anaconda3/envs/snorkel/lib/python3.6/site-packages/sqlalchemy/orm/unitofwork.py\", line 391, in execute\n",
      "    rec.execute(self)\n",
      "  File \"/lfs/local/0/jdunnmon/repos/anaconda3/envs/snorkel/lib/python3.6/site-packages/sqlalchemy/orm/unitofwork.py\", line 556, in execute\n",
      "    uow\n"
     ]
    },
    {
     "name": "stderr",
     "output_type": "stream",
     "text": [
      "Process CandidateExtractorUDF-31:\n",
      "  File \"/lfs/local/0/jdunnmon/repos/anaconda3/envs/snorkel/lib/python3.6/site-packages/sqlalchemy/orm/persistence.py\", line 181, in save_obj\n",
      "    mapper, table, insert)\n",
      "  File \"/lfs/local/0/jdunnmon/repos/anaconda3/envs/snorkel/lib/python3.6/site-packages/sqlalchemy/orm/persistence.py\", line 830, in _emit_insert_statements\n",
      "    execute(statement, multiparams)\n",
      "  File \"/lfs/local/0/jdunnmon/repos/anaconda3/envs/snorkel/lib/python3.6/site-packages/sqlalchemy/engine/base.py\", line 948, in execute\n",
      "    return meth(self, multiparams, params)\n",
      "  File \"/lfs/local/0/jdunnmon/repos/anaconda3/envs/snorkel/lib/python3.6/site-packages/sqlalchemy/sql/elements.py\", line 269, in _execute_on_connection\n",
      "    return connection._execute_clauseelement(self, multiparams, params)\n",
      "  File \"/lfs/local/0/jdunnmon/repos/anaconda3/envs/snorkel/lib/python3.6/site-packages/sqlalchemy/engine/base.py\", line 1060, in _execute_clauseelement\n",
      "    compiled_sql, distilled_params\n",
      "  File \"/lfs/local/0/jdunnmon/repos/anaconda3/envs/snorkel/lib/python3.6/site-packages/sqlalchemy/engine/base.py\", line 1200, in _execute_context\n",
      "    context)\n",
      "  File \"/lfs/local/0/jdunnmon/repos/anaconda3/envs/snorkel/lib/python3.6/site-packages/sqlalchemy/engine/base.py\", line 1413, in _handle_dbapi_exception\n",
      "    exc_info\n",
      "  File \"/lfs/local/0/jdunnmon/repos/anaconda3/envs/snorkel/lib/python3.6/site-packages/sqlalchemy/util/compat.py\", line 203, in raise_from_cause\n",
      "    reraise(type(exception), exception, tb=exc_tb, cause=cause)\n",
      "  File \"/lfs/local/0/jdunnmon/repos/anaconda3/envs/snorkel/lib/python3.6/site-packages/sqlalchemy/util/compat.py\", line 186, in reraise\n",
      "    raise value.with_traceback(tb)\n",
      "Traceback (most recent call last):\n",
      "  File \"/lfs/local/0/jdunnmon/repos/anaconda3/envs/snorkel/lib/python3.6/site-packages/sqlalchemy/engine/base.py\", line 1170, in _execute_context\n",
      "    context)\n",
      "  File \"/lfs/local/0/jdunnmon/repos/anaconda3/envs/snorkel/lib/python3.6/site-packages/sqlalchemy/engine/base.py\", line 1170, in _execute_context\n",
      "    context)\n",
      "  File \"/lfs/local/0/jdunnmon/repos/anaconda3/envs/snorkel/lib/python3.6/site-packages/sqlalchemy/dialects/postgresql/psycopg2.py\", line 683, in do_executemany\n",
      "    cursor.executemany(statement, parameters)\n",
      "  File \"/lfs/local/0/jdunnmon/repos/anaconda3/envs/snorkel/lib/python3.6/site-packages/sqlalchemy/dialects/postgresql/psycopg2.py\", line 683, in do_executemany\n",
      "    cursor.executemany(statement, parameters)\n",
      "sqlalchemy.exc.IntegrityError: (psycopg2.IntegrityError) duplicate key value violates unique constraint \"location_location_id_key\"\n",
      "DETAIL:  Key (location_id)=(241538) already exists.\n",
      " [SQL: 'INSERT INTO location (id, location_id, location_cid) VALUES (%(id)s, %(location_id)s, %(location_cid)s)'] [parameters: ({'id': 66443, 'location_id': 239267, 'location_cid': None}, {'id': 66444, 'location_id': 239283, 'location_cid': None}, {'id': 66447, 'location_id': 239278, 'location_cid': None}, {'id': 66458, 'location_id': 239288, 'location_cid': None}, {'id': 66476, 'location_id': 239310, 'location_cid': None}, {'id': 66491, 'location_id': 239335, 'location_cid': None}, {'id': 66505, 'location_id': 239349, 'location_cid': None}, {'id': 66523, 'location_id': 239351, 'location_cid': None}  ... displaying 10 of 5767 total bound parameter sets ...  {'id': 158192, 'location_id': 330011, 'location_cid': None}, {'id': 158204, 'location_id': 330076, 'location_cid': None})] (Background on this error at: http://sqlalche.me/e/gkpj)\n",
      "psycopg2.IntegrityError: duplicate key value violates unique constraint \"location_location_id_key\"\n",
      "DETAIL:  Key (location_id)=(239636) already exists.\n",
      "\n",
      "\n",
      "The above exception was the direct cause of the following exception:\n",
      "\n",
      "Traceback (most recent call last):\n",
      "  File \"/lfs/local/0/jdunnmon/repos/anaconda3/envs/snorkel/lib/python3.6/multiprocessing/process.py\", line 258, in _bootstrap\n",
      "    self.run()\n",
      "  File \"/lfs/raiders5/0/jdunnmon/repos/snorkel/snorkel/udf.py\", line 170, in run\n",
      "    self.session.commit()\n",
      "  File \"/lfs/local/0/jdunnmon/repos/anaconda3/envs/snorkel/lib/python3.6/site-packages/sqlalchemy/orm/session.py\", line 943, in commit\n",
      "    self.transaction.commit()\n",
      "  File \"/lfs/local/0/jdunnmon/repos/anaconda3/envs/snorkel/lib/python3.6/site-packages/sqlalchemy/orm/session.py\", line 467, in commit\n",
      "    self._prepare_impl()\n",
      "  File \"/lfs/local/0/jdunnmon/repos/anaconda3/envs/snorkel/lib/python3.6/site-packages/sqlalchemy/orm/session.py\", line 447, in _prepare_impl\n",
      "    self.session.flush()\n",
      "  File \"/lfs/local/0/jdunnmon/repos/anaconda3/envs/snorkel/lib/python3.6/site-packages/sqlalchemy/orm/session.py\", line 2254, in flush\n",
      "    self._flush(objects)\n",
      "  File \"/lfs/local/0/jdunnmon/repos/anaconda3/envs/snorkel/lib/python3.6/site-packages/sqlalchemy/orm/session.py\", line 2380, in _flush\n",
      "    transaction.rollback(_capture_exception=True)\n",
      "  File \"/lfs/local/0/jdunnmon/repos/anaconda3/envs/snorkel/lib/python3.6/site-packages/sqlalchemy/util/langhelpers.py\", line 66, in __exit__\n",
      "    compat.reraise(exc_type, exc_value, exc_tb)\n",
      "  File \"/lfs/local/0/jdunnmon/repos/anaconda3/envs/snorkel/lib/python3.6/site-packages/sqlalchemy/util/compat.py\", line 187, in reraise\n",
      "    raise value\n",
      "  File \"/lfs/local/0/jdunnmon/repos/anaconda3/envs/snorkel/lib/python3.6/site-packages/sqlalchemy/orm/session.py\", line 2344, in _flush\n",
      "    flush_context.execute()\n",
      "  File \"/lfs/local/0/jdunnmon/repos/anaconda3/envs/snorkel/lib/python3.6/site-packages/sqlalchemy/orm/unitofwork.py\", line 391, in execute\n",
      "    rec.execute(self)\n",
      "  File \"/lfs/local/0/jdunnmon/repos/anaconda3/envs/snorkel/lib/python3.6/site-packages/sqlalchemy/orm/unitofwork.py\", line 556, in execute\n",
      "    uow\n",
      "  File \"/lfs/local/0/jdunnmon/repos/anaconda3/envs/snorkel/lib/python3.6/site-packages/sqlalchemy/orm/persistence.py\", line 181, in save_obj\n",
      "    mapper, table, insert)\n",
      "  File \"/lfs/local/0/jdunnmon/repos/anaconda3/envs/snorkel/lib/python3.6/site-packages/sqlalchemy/orm/persistence.py\", line 830, in _emit_insert_statements\n",
      "    execute(statement, multiparams)\n",
      "  File \"/lfs/local/0/jdunnmon/repos/anaconda3/envs/snorkel/lib/python3.6/site-packages/sqlalchemy/engine/base.py\", line 948, in execute\n",
      "    return meth(self, multiparams, params)\n",
      "  File \"/lfs/local/0/jdunnmon/repos/anaconda3/envs/snorkel/lib/python3.6/site-packages/sqlalchemy/sql/elements.py\", line 269, in _execute_on_connection\n",
      "    return connection._execute_clauseelement(self, multiparams, params)\n",
      "  File \"/lfs/local/0/jdunnmon/repos/anaconda3/envs/snorkel/lib/python3.6/site-packages/sqlalchemy/engine/base.py\", line 1060, in _execute_clauseelement\n",
      "    compiled_sql, distilled_params\n",
      "  File \"/lfs/local/0/jdunnmon/repos/anaconda3/envs/snorkel/lib/python3.6/site-packages/sqlalchemy/engine/base.py\", line 1200, in _execute_context\n",
      "    context)\n",
      "  File \"/lfs/local/0/jdunnmon/repos/anaconda3/envs/snorkel/lib/python3.6/site-packages/sqlalchemy/engine/base.py\", line 1413, in _handle_dbapi_exception\n",
      "    exc_info\n",
      "  File \"/lfs/local/0/jdunnmon/repos/anaconda3/envs/snorkel/lib/python3.6/site-packages/sqlalchemy/util/compat.py\", line 203, in raise_from_cause\n",
      "    reraise(type(exception), exception, tb=exc_tb, cause=cause)\n",
      "  File \"/lfs/local/0/jdunnmon/repos/anaconda3/envs/snorkel/lib/python3.6/site-packages/sqlalchemy/util/compat.py\", line 186, in reraise\n",
      "    raise value.with_traceback(tb)\n",
      "  File \"/lfs/local/0/jdunnmon/repos/anaconda3/envs/snorkel/lib/python3.6/site-packages/sqlalchemy/engine/base.py\", line 1170, in _execute_context\n",
      "    context)\n",
      "  File \"/lfs/local/0/jdunnmon/repos/anaconda3/envs/snorkel/lib/python3.6/site-packages/sqlalchemy/dialects/postgresql/psycopg2.py\", line 683, in do_executemany\n",
      "    cursor.executemany(statement, parameters)\n",
      "sqlalchemy.exc.IntegrityError: (psycopg2.IntegrityError) duplicate key value violates unique constraint \"location_location_id_key\"\n",
      "DETAIL:  Key (location_id)=(239636) already exists.\n",
      " [SQL: 'INSERT INTO location (id, location_id, location_cid) VALUES (%(id)s, %(location_id)s, %(location_cid)s)'] [parameters: ({'id': 66456, 'location_id': 239327, 'location_cid': None}, {'id': 66468, 'location_id': 239320, 'location_cid': None}, {'id': 66483, 'location_id': 239323, 'location_cid': None}, {'id': 66496, 'location_id': 239312, 'location_cid': None}, {'id': 66513, 'location_id': 239449, 'location_cid': None}, {'id': 66535, 'location_id': 239452, 'location_cid': None}, {'id': 66547, 'location_id': 239457, 'location_cid': None}, {'id': 66567, 'location_id': 239476, 'location_cid': None}  ... displaying 10 of 5883 total bound parameter sets ...  {'id': 158926, 'location_id': 330114, 'location_cid': None}, {'id': 158930, 'location_id': 330139, 'location_cid': None})] (Background on this error at: http://sqlalche.me/e/gkpj)\n"
     ]
    },
    {
     "name": "stderr",
     "output_type": "stream",
     "text": [
      "Process CandidateExtractorUDF-29:\n",
      "Traceback (most recent call last):\n",
      "  File \"/lfs/local/0/jdunnmon/repos/anaconda3/envs/snorkel/lib/python3.6/site-packages/sqlalchemy/engine/base.py\", line 1170, in _execute_context\n",
      "    context)\n",
      "  File \"/lfs/local/0/jdunnmon/repos/anaconda3/envs/snorkel/lib/python3.6/site-packages/sqlalchemy/dialects/postgresql/psycopg2.py\", line 683, in do_executemany\n",
      "    cursor.executemany(statement, parameters)\n",
      "psycopg2.IntegrityError: duplicate key value violates unique constraint \"location_location_id_key\"\n",
      "DETAIL:  Key (location_id)=(241890) already exists.\n",
      "\n",
      "\n",
      "The above exception was the direct cause of the following exception:\n",
      "\n",
      "Traceback (most recent call last):\n",
      "  File \"/lfs/local/0/jdunnmon/repos/anaconda3/envs/snorkel/lib/python3.6/multiprocessing/process.py\", line 258, in _bootstrap\n",
      "    self.run()\n",
      "  File \"/lfs/raiders5/0/jdunnmon/repos/snorkel/snorkel/udf.py\", line 170, in run\n",
      "    self.session.commit()\n",
      "  File \"/lfs/local/0/jdunnmon/repos/anaconda3/envs/snorkel/lib/python3.6/site-packages/sqlalchemy/orm/session.py\", line 943, in commit\n",
      "    self.transaction.commit()\n",
      "  File \"/lfs/local/0/jdunnmon/repos/anaconda3/envs/snorkel/lib/python3.6/site-packages/sqlalchemy/orm/session.py\", line 467, in commit\n",
      "    self._prepare_impl()\n",
      "  File \"/lfs/local/0/jdunnmon/repos/anaconda3/envs/snorkel/lib/python3.6/site-packages/sqlalchemy/orm/session.py\", line 447, in _prepare_impl\n",
      "    self.session.flush()\n",
      "  File \"/lfs/local/0/jdunnmon/repos/anaconda3/envs/snorkel/lib/python3.6/site-packages/sqlalchemy/orm/session.py\", line 2254, in flush\n",
      "    self._flush(objects)\n",
      "  File \"/lfs/local/0/jdunnmon/repos/anaconda3/envs/snorkel/lib/python3.6/site-packages/sqlalchemy/orm/session.py\", line 2380, in _flush\n",
      "    transaction.rollback(_capture_exception=True)\n",
      "  File \"/lfs/local/0/jdunnmon/repos/anaconda3/envs/snorkel/lib/python3.6/site-packages/sqlalchemy/util/langhelpers.py\", line 66, in __exit__\n",
      "    compat.reraise(exc_type, exc_value, exc_tb)\n",
      "  File \"/lfs/local/0/jdunnmon/repos/anaconda3/envs/snorkel/lib/python3.6/site-packages/sqlalchemy/util/compat.py\", line 187, in reraise\n",
      "    raise value\n",
      "  File \"/lfs/local/0/jdunnmon/repos/anaconda3/envs/snorkel/lib/python3.6/site-packages/sqlalchemy/orm/session.py\", line 2344, in _flush\n",
      "    flush_context.execute()\n",
      "  File \"/lfs/local/0/jdunnmon/repos/anaconda3/envs/snorkel/lib/python3.6/site-packages/sqlalchemy/orm/unitofwork.py\", line 391, in execute\n",
      "    rec.execute(self)\n",
      "  File \"/lfs/local/0/jdunnmon/repos/anaconda3/envs/snorkel/lib/python3.6/site-packages/sqlalchemy/orm/unitofwork.py\", line 556, in execute\n",
      "    uow\n",
      "  File \"/lfs/local/0/jdunnmon/repos/anaconda3/envs/snorkel/lib/python3.6/site-packages/sqlalchemy/orm/persistence.py\", line 181, in save_obj\n",
      "    mapper, table, insert)\n",
      "  File \"/lfs/local/0/jdunnmon/repos/anaconda3/envs/snorkel/lib/python3.6/site-packages/sqlalchemy/orm/persistence.py\", line 830, in _emit_insert_statements\n",
      "    execute(statement, multiparams)\n",
      "  File \"/lfs/local/0/jdunnmon/repos/anaconda3/envs/snorkel/lib/python3.6/site-packages/sqlalchemy/engine/base.py\", line 948, in execute\n",
      "    return meth(self, multiparams, params)\n",
      "  File \"/lfs/local/0/jdunnmon/repos/anaconda3/envs/snorkel/lib/python3.6/site-packages/sqlalchemy/sql/elements.py\", line 269, in _execute_on_connection\n",
      "    return connection._execute_clauseelement(self, multiparams, params)\n",
      "  File \"/lfs/local/0/jdunnmon/repos/anaconda3/envs/snorkel/lib/python3.6/site-packages/sqlalchemy/engine/base.py\", line 1060, in _execute_clauseelement\n",
      "    compiled_sql, distilled_params\n",
      "  File \"/lfs/local/0/jdunnmon/repos/anaconda3/envs/snorkel/lib/python3.6/site-packages/sqlalchemy/engine/base.py\", line 1200, in _execute_context\n",
      "    context)\n",
      "  File \"/lfs/local/0/jdunnmon/repos/anaconda3/envs/snorkel/lib/python3.6/site-packages/sqlalchemy/engine/base.py\", line 1413, in _handle_dbapi_exception\n",
      "    exc_info\n",
      "  File \"/lfs/local/0/jdunnmon/repos/anaconda3/envs/snorkel/lib/python3.6/site-packages/sqlalchemy/util/compat.py\", line 203, in raise_from_cause\n",
      "    reraise(type(exception), exception, tb=exc_tb, cause=cause)\n",
      "  File \"/lfs/local/0/jdunnmon/repos/anaconda3/envs/snorkel/lib/python3.6/site-packages/sqlalchemy/util/compat.py\", line 186, in reraise\n",
      "    raise value.with_traceback(tb)\n",
      "  File \"/lfs/local/0/jdunnmon/repos/anaconda3/envs/snorkel/lib/python3.6/site-packages/sqlalchemy/engine/base.py\", line 1170, in _execute_context\n",
      "    context)\n",
      "  File \"/lfs/local/0/jdunnmon/repos/anaconda3/envs/snorkel/lib/python3.6/site-packages/sqlalchemy/dialects/postgresql/psycopg2.py\", line 683, in do_executemany\n",
      "    cursor.executemany(statement, parameters)\n",
      "sqlalchemy.exc.IntegrityError: (psycopg2.IntegrityError) duplicate key value violates unique constraint \"location_location_id_key\"\n",
      "DETAIL:  Key (location_id)=(241890) already exists.\n",
      " [SQL: 'INSERT INTO location (id, location_id, location_cid) VALUES (%(id)s, %(location_id)s, %(location_cid)s)'] [parameters: ({'id': 66451, 'location_id': 239307, 'location_cid': None}, {'id': 66466, 'location_id': 239314, 'location_cid': None}, {'id': 66481, 'location_id': 239383, 'location_cid': None}, {'id': 66501, 'location_id': 239389, 'location_cid': None}, {'id': 66518, 'location_id': 239401, 'location_cid': None}, {'id': 66533, 'location_id': 239406, 'location_cid': None}, {'id': 66550, 'location_id': 239432, 'location_cid': None}, {'id': 66561, 'location_id': 239441, 'location_cid': None}  ... displaying 10 of 5760 total bound parameter sets ...  {'id': 158199, 'location_id': 330094, 'location_cid': None}, {'id': 158205, 'location_id': 330097, 'location_cid': None})] (Background on this error at: http://sqlalche.me/e/gkpj)\n",
      "Process CandidateExtractorUDF-20:\n",
      "Traceback (most recent call last):\n",
      "  File \"/lfs/local/0/jdunnmon/repos/anaconda3/envs/snorkel/lib/python3.6/site-packages/sqlalchemy/engine/base.py\", line 1170, in _execute_context\n",
      "    context)\n",
      "  File \"/lfs/local/0/jdunnmon/repos/anaconda3/envs/snorkel/lib/python3.6/site-packages/sqlalchemy/dialects/postgresql/psycopg2.py\", line 683, in do_executemany\n",
      "    cursor.executemany(statement, parameters)\n",
      "psycopg2.IntegrityError: duplicate key value violates unique constraint \"location_location_id_key\"\n",
      "DETAIL:  Key (location_id)=(239532) already exists.\n",
      "\n",
      "\n",
      "The above exception was the direct cause of the following exception:\n",
      "\n",
      "Traceback (most recent call last):\n",
      "  File \"/lfs/local/0/jdunnmon/repos/anaconda3/envs/snorkel/lib/python3.6/multiprocessing/process.py\", line 258, in _bootstrap\n",
      "    self.run()\n",
      "  File \"/lfs/raiders5/0/jdunnmon/repos/snorkel/snorkel/udf.py\", line 170, in run\n",
      "    self.session.commit()\n",
      "  File \"/lfs/local/0/jdunnmon/repos/anaconda3/envs/snorkel/lib/python3.6/site-packages/sqlalchemy/orm/session.py\", line 943, in commit\n",
      "    self.transaction.commit()\n",
      "  File \"/lfs/local/0/jdunnmon/repos/anaconda3/envs/snorkel/lib/python3.6/site-packages/sqlalchemy/orm/session.py\", line 467, in commit\n",
      "    self._prepare_impl()\n",
      "  File \"/lfs/local/0/jdunnmon/repos/anaconda3/envs/snorkel/lib/python3.6/site-packages/sqlalchemy/orm/session.py\", line 447, in _prepare_impl\n",
      "    self.session.flush()\n",
      "  File \"/lfs/local/0/jdunnmon/repos/anaconda3/envs/snorkel/lib/python3.6/site-packages/sqlalchemy/orm/session.py\", line 2254, in flush\n",
      "    self._flush(objects)\n",
      "  File \"/lfs/local/0/jdunnmon/repos/anaconda3/envs/snorkel/lib/python3.6/site-packages/sqlalchemy/orm/session.py\", line 2380, in _flush\n",
      "    transaction.rollback(_capture_exception=True)\n",
      "  File \"/lfs/local/0/jdunnmon/repos/anaconda3/envs/snorkel/lib/python3.6/site-packages/sqlalchemy/util/langhelpers.py\", line 66, in __exit__\n",
      "    compat.reraise(exc_type, exc_value, exc_tb)\n",
      "  File \"/lfs/local/0/jdunnmon/repos/anaconda3/envs/snorkel/lib/python3.6/site-packages/sqlalchemy/util/compat.py\", line 187, in reraise\n",
      "    raise value\n",
      "  File \"/lfs/local/0/jdunnmon/repos/anaconda3/envs/snorkel/lib/python3.6/site-packages/sqlalchemy/orm/session.py\", line 2344, in _flush\n",
      "    flush_context.execute()\n",
      "  File \"/lfs/local/0/jdunnmon/repos/anaconda3/envs/snorkel/lib/python3.6/site-packages/sqlalchemy/orm/unitofwork.py\", line 391, in execute\n",
      "    rec.execute(self)\n",
      "  File \"/lfs/local/0/jdunnmon/repos/anaconda3/envs/snorkel/lib/python3.6/site-packages/sqlalchemy/orm/unitofwork.py\", line 556, in execute\n",
      "    uow\n"
     ]
    },
    {
     "name": "stderr",
     "output_type": "stream",
     "text": [
      "  File \"/lfs/local/0/jdunnmon/repos/anaconda3/envs/snorkel/lib/python3.6/site-packages/sqlalchemy/orm/persistence.py\", line 181, in save_obj\n",
      "    mapper, table, insert)\n",
      "  File \"/lfs/local/0/jdunnmon/repos/anaconda3/envs/snorkel/lib/python3.6/site-packages/sqlalchemy/orm/persistence.py\", line 830, in _emit_insert_statements\n",
      "    execute(statement, multiparams)\n",
      "  File \"/lfs/local/0/jdunnmon/repos/anaconda3/envs/snorkel/lib/python3.6/site-packages/sqlalchemy/engine/base.py\", line 948, in execute\n",
      "    return meth(self, multiparams, params)\n",
      "  File \"/lfs/local/0/jdunnmon/repos/anaconda3/envs/snorkel/lib/python3.6/site-packages/sqlalchemy/sql/elements.py\", line 269, in _execute_on_connection\n",
      "    return connection._execute_clauseelement(self, multiparams, params)\n",
      "  File \"/lfs/local/0/jdunnmon/repos/anaconda3/envs/snorkel/lib/python3.6/site-packages/sqlalchemy/engine/base.py\", line 1060, in _execute_clauseelement\n",
      "    compiled_sql, distilled_params\n",
      "  File \"/lfs/local/0/jdunnmon/repos/anaconda3/envs/snorkel/lib/python3.6/site-packages/sqlalchemy/engine/base.py\", line 1200, in _execute_context\n",
      "    context)\n",
      "  File \"/lfs/local/0/jdunnmon/repos/anaconda3/envs/snorkel/lib/python3.6/site-packages/sqlalchemy/engine/base.py\", line 1413, in _handle_dbapi_exception\n",
      "    exc_info\n",
      "  File \"/lfs/local/0/jdunnmon/repos/anaconda3/envs/snorkel/lib/python3.6/site-packages/sqlalchemy/util/compat.py\", line 203, in raise_from_cause\n",
      "    reraise(type(exception), exception, tb=exc_tb, cause=cause)\n",
      "  File \"/lfs/local/0/jdunnmon/repos/anaconda3/envs/snorkel/lib/python3.6/site-packages/sqlalchemy/util/compat.py\", line 186, in reraise\n",
      "    raise value.with_traceback(tb)\n",
      "  File \"/lfs/local/0/jdunnmon/repos/anaconda3/envs/snorkel/lib/python3.6/site-packages/sqlalchemy/engine/base.py\", line 1170, in _execute_context\n",
      "    context)\n",
      "  File \"/lfs/local/0/jdunnmon/repos/anaconda3/envs/snorkel/lib/python3.6/site-packages/sqlalchemy/dialects/postgresql/psycopg2.py\", line 683, in do_executemany\n",
      "    cursor.executemany(statement, parameters)\n",
      "sqlalchemy.exc.IntegrityError: (psycopg2.IntegrityError) duplicate key value violates unique constraint \"location_location_id_key\"\n",
      "DETAIL:  Key (location_id)=(239532) already exists.\n",
      " [SQL: 'INSERT INTO location (id, location_id, location_cid) VALUES (%(id)s, %(location_id)s, %(location_cid)s)'] [parameters: ({'id': 66455, 'location_id': 239254, 'location_cid': None}, {'id': 66467, 'location_id': 239260, 'location_cid': None}, {'id': 66482, 'location_id': 239282, 'location_cid': None}, {'id': 66498, 'location_id': 239290, 'location_cid': None}, {'id': 66514, 'location_id': 239271, 'location_cid': None}, {'id': 66534, 'location_id': 239297, 'location_cid': None}, {'id': 66549, 'location_id': 239303, 'location_cid': None}, {'id': 66562, 'location_id': 239275, 'location_cid': None}  ... displaying 10 of 5924 total bound parameter sets ...  {'id': 159023, 'location_id': 330135, 'location_cid': None}, {'id': 159026, 'location_id': 330129, 'location_cid': None})] (Background on this error at: http://sqlalche.me/e/gkpj)\n",
      "Process CandidateExtractorUDF-32:\n",
      "Traceback (most recent call last):\n",
      "  File \"/lfs/local/0/jdunnmon/repos/anaconda3/envs/snorkel/lib/python3.6/site-packages/sqlalchemy/engine/base.py\", line 1170, in _execute_context\n",
      "    context)\n",
      "  File \"/lfs/local/0/jdunnmon/repos/anaconda3/envs/snorkel/lib/python3.6/site-packages/sqlalchemy/dialects/postgresql/psycopg2.py\", line 683, in do_executemany\n",
      "    cursor.executemany(statement, parameters)\n",
      "psycopg2.IntegrityError: duplicate key value violates unique constraint \"location_location_id_key\"\n",
      "DETAIL:  Key (location_id)=(239491) already exists.\n",
      "\n",
      "\n",
      "The above exception was the direct cause of the following exception:\n",
      "\n",
      "Traceback (most recent call last):\n",
      "  File \"/lfs/local/0/jdunnmon/repos/anaconda3/envs/snorkel/lib/python3.6/multiprocessing/process.py\", line 258, in _bootstrap\n",
      "    self.run()\n",
      "  File \"/lfs/raiders5/0/jdunnmon/repos/snorkel/snorkel/udf.py\", line 170, in run\n",
      "    self.session.commit()\n",
      "  File \"/lfs/local/0/jdunnmon/repos/anaconda3/envs/snorkel/lib/python3.6/site-packages/sqlalchemy/orm/session.py\", line 943, in commit\n",
      "    self.transaction.commit()\n",
      "  File \"/lfs/local/0/jdunnmon/repos/anaconda3/envs/snorkel/lib/python3.6/site-packages/sqlalchemy/orm/session.py\", line 467, in commit\n",
      "    self._prepare_impl()\n",
      "  File \"/lfs/local/0/jdunnmon/repos/anaconda3/envs/snorkel/lib/python3.6/site-packages/sqlalchemy/orm/session.py\", line 447, in _prepare_impl\n",
      "    self.session.flush()\n",
      "  File \"/lfs/local/0/jdunnmon/repos/anaconda3/envs/snorkel/lib/python3.6/site-packages/sqlalchemy/orm/session.py\", line 2254, in flush\n",
      "    self._flush(objects)\n",
      "  File \"/lfs/local/0/jdunnmon/repos/anaconda3/envs/snorkel/lib/python3.6/site-packages/sqlalchemy/orm/session.py\", line 2380, in _flush\n",
      "    transaction.rollback(_capture_exception=True)\n",
      "  File \"/lfs/local/0/jdunnmon/repos/anaconda3/envs/snorkel/lib/python3.6/site-packages/sqlalchemy/util/langhelpers.py\", line 66, in __exit__\n",
      "    compat.reraise(exc_type, exc_value, exc_tb)\n",
      "  File \"/lfs/local/0/jdunnmon/repos/anaconda3/envs/snorkel/lib/python3.6/site-packages/sqlalchemy/util/compat.py\", line 187, in reraise\n",
      "    raise value\n",
      "  File \"/lfs/local/0/jdunnmon/repos/anaconda3/envs/snorkel/lib/python3.6/site-packages/sqlalchemy/orm/session.py\", line 2344, in _flush\n",
      "    flush_context.execute()\n",
      "  File \"/lfs/local/0/jdunnmon/repos/anaconda3/envs/snorkel/lib/python3.6/site-packages/sqlalchemy/orm/unitofwork.py\", line 391, in execute\n",
      "    rec.execute(self)\n",
      "  File \"/lfs/local/0/jdunnmon/repos/anaconda3/envs/snorkel/lib/python3.6/site-packages/sqlalchemy/orm/unitofwork.py\", line 556, in execute\n",
      "    uow\n",
      "  File \"/lfs/local/0/jdunnmon/repos/anaconda3/envs/snorkel/lib/python3.6/site-packages/sqlalchemy/orm/persistence.py\", line 181, in save_obj\n",
      "    mapper, table, insert)\n",
      "  File \"/lfs/local/0/jdunnmon/repos/anaconda3/envs/snorkel/lib/python3.6/site-packages/sqlalchemy/orm/persistence.py\", line 830, in _emit_insert_statements\n",
      "    execute(statement, multiparams)\n",
      "  File \"/lfs/local/0/jdunnmon/repos/anaconda3/envs/snorkel/lib/python3.6/site-packages/sqlalchemy/engine/base.py\", line 948, in execute\n",
      "    return meth(self, multiparams, params)\n",
      "  File \"/lfs/local/0/jdunnmon/repos/anaconda3/envs/snorkel/lib/python3.6/site-packages/sqlalchemy/sql/elements.py\", line 269, in _execute_on_connection\n",
      "    return connection._execute_clauseelement(self, multiparams, params)\n",
      "  File \"/lfs/local/0/jdunnmon/repos/anaconda3/envs/snorkel/lib/python3.6/site-packages/sqlalchemy/engine/base.py\", line 1060, in _execute_clauseelement\n",
      "    compiled_sql, distilled_params\n",
      "  File \"/lfs/local/0/jdunnmon/repos/anaconda3/envs/snorkel/lib/python3.6/site-packages/sqlalchemy/engine/base.py\", line 1200, in _execute_context\n",
      "    context)\n",
      "  File \"/lfs/local/0/jdunnmon/repos/anaconda3/envs/snorkel/lib/python3.6/site-packages/sqlalchemy/engine/base.py\", line 1413, in _handle_dbapi_exception\n",
      "    exc_info\n",
      "  File \"/lfs/local/0/jdunnmon/repos/anaconda3/envs/snorkel/lib/python3.6/site-packages/sqlalchemy/util/compat.py\", line 203, in raise_from_cause\n",
      "    reraise(type(exception), exception, tb=exc_tb, cause=cause)\n",
      "  File \"/lfs/local/0/jdunnmon/repos/anaconda3/envs/snorkel/lib/python3.6/site-packages/sqlalchemy/util/compat.py\", line 186, in reraise\n",
      "    raise value.with_traceback(tb)\n",
      "  File \"/lfs/local/0/jdunnmon/repos/anaconda3/envs/snorkel/lib/python3.6/site-packages/sqlalchemy/engine/base.py\", line 1170, in _execute_context\n",
      "    context)\n",
      "  File \"/lfs/local/0/jdunnmon/repos/anaconda3/envs/snorkel/lib/python3.6/site-packages/sqlalchemy/dialects/postgresql/psycopg2.py\", line 683, in do_executemany\n",
      "    cursor.executemany(statement, parameters)\n",
      "sqlalchemy.exc.IntegrityError: (psycopg2.IntegrityError) duplicate key value violates unique constraint \"location_location_id_key\"\n",
      "DETAIL:  Key (location_id)=(239491) already exists.\n",
      " [SQL: 'INSERT INTO location (id, location_id, location_cid) VALUES (%(id)s, %(location_id)s, %(location_cid)s)'] [parameters: ({'id': 66471, 'location_id': 239317, 'location_cid': None}, {'id': 66486, 'location_id': 239344, 'location_cid': None}, {'id': 66494, 'location_id': 239357, 'location_cid': None}, {'id': 66510, 'location_id': 239365, 'location_cid': None}, {'id': 66530, 'location_id': 239397, 'location_cid': None}, {'id': 66545, 'location_id': 239429, 'location_cid': None}, {'id': 66559, 'location_id': 239411, 'location_cid': None}, {'id': 66576, 'location_id': 239405, 'location_cid': None}  ... displaying 10 of 5957 total bound parameter sets ...  {'id': 159099, 'location_id': 330143, 'location_cid': None}, {'id': 159101, 'location_id': 330138, 'location_cid': None})] (Background on this error at: http://sqlalche.me/e/gkpj)\n"
     ]
    },
    {
     "name": "stderr",
     "output_type": "stream",
     "text": [
      "Process CandidateExtractorUDF-25:\n",
      "Traceback (most recent call last):\n",
      "  File \"/lfs/local/0/jdunnmon/repos/anaconda3/envs/snorkel/lib/python3.6/site-packages/sqlalchemy/engine/base.py\", line 1170, in _execute_context\n",
      "    context)\n",
      "  File \"/lfs/local/0/jdunnmon/repos/anaconda3/envs/snorkel/lib/python3.6/site-packages/sqlalchemy/dialects/postgresql/psycopg2.py\", line 683, in do_executemany\n",
      "    cursor.executemany(statement, parameters)\n",
      "psycopg2.IntegrityError: duplicate key value violates unique constraint \"location_location_id_key\"\n",
      "DETAIL:  Key (location_id)=(242946) already exists.\n",
      "\n",
      "\n",
      "The above exception was the direct cause of the following exception:\n",
      "\n",
      "Traceback (most recent call last):\n",
      "  File \"/lfs/local/0/jdunnmon/repos/anaconda3/envs/snorkel/lib/python3.6/multiprocessing/process.py\", line 258, in _bootstrap\n",
      "    self.run()\n",
      "  File \"/lfs/raiders5/0/jdunnmon/repos/snorkel/snorkel/udf.py\", line 170, in run\n",
      "    self.session.commit()\n",
      "  File \"/lfs/local/0/jdunnmon/repos/anaconda3/envs/snorkel/lib/python3.6/site-packages/sqlalchemy/orm/session.py\", line 943, in commit\n",
      "    self.transaction.commit()\n",
      "  File \"/lfs/local/0/jdunnmon/repos/anaconda3/envs/snorkel/lib/python3.6/site-packages/sqlalchemy/orm/session.py\", line 467, in commit\n",
      "    self._prepare_impl()\n",
      "  File \"/lfs/local/0/jdunnmon/repos/anaconda3/envs/snorkel/lib/python3.6/site-packages/sqlalchemy/orm/session.py\", line 447, in _prepare_impl\n",
      "    self.session.flush()\n",
      "  File \"/lfs/local/0/jdunnmon/repos/anaconda3/envs/snorkel/lib/python3.6/site-packages/sqlalchemy/orm/session.py\", line 2254, in flush\n",
      "    self._flush(objects)\n",
      "  File \"/lfs/local/0/jdunnmon/repos/anaconda3/envs/snorkel/lib/python3.6/site-packages/sqlalchemy/orm/session.py\", line 2380, in _flush\n",
      "    transaction.rollback(_capture_exception=True)\n",
      "  File \"/lfs/local/0/jdunnmon/repos/anaconda3/envs/snorkel/lib/python3.6/site-packages/sqlalchemy/util/langhelpers.py\", line 66, in __exit__\n",
      "    compat.reraise(exc_type, exc_value, exc_tb)\n",
      "  File \"/lfs/local/0/jdunnmon/repos/anaconda3/envs/snorkel/lib/python3.6/site-packages/sqlalchemy/util/compat.py\", line 187, in reraise\n",
      "    raise value\n",
      "  File \"/lfs/local/0/jdunnmon/repos/anaconda3/envs/snorkel/lib/python3.6/site-packages/sqlalchemy/orm/session.py\", line 2344, in _flush\n",
      "    flush_context.execute()\n",
      "  File \"/lfs/local/0/jdunnmon/repos/anaconda3/envs/snorkel/lib/python3.6/site-packages/sqlalchemy/orm/unitofwork.py\", line 391, in execute\n",
      "    rec.execute(self)\n",
      "  File \"/lfs/local/0/jdunnmon/repos/anaconda3/envs/snorkel/lib/python3.6/site-packages/sqlalchemy/orm/unitofwork.py\", line 556, in execute\n",
      "    uow\n",
      "  File \"/lfs/local/0/jdunnmon/repos/anaconda3/envs/snorkel/lib/python3.6/site-packages/sqlalchemy/orm/persistence.py\", line 181, in save_obj\n",
      "    mapper, table, insert)\n",
      "  File \"/lfs/local/0/jdunnmon/repos/anaconda3/envs/snorkel/lib/python3.6/site-packages/sqlalchemy/orm/persistence.py\", line 830, in _emit_insert_statements\n",
      "    execute(statement, multiparams)\n",
      "  File \"/lfs/local/0/jdunnmon/repos/anaconda3/envs/snorkel/lib/python3.6/site-packages/sqlalchemy/engine/base.py\", line 948, in execute\n",
      "    return meth(self, multiparams, params)\n",
      "  File \"/lfs/local/0/jdunnmon/repos/anaconda3/envs/snorkel/lib/python3.6/site-packages/sqlalchemy/sql/elements.py\", line 269, in _execute_on_connection\n",
      "    return connection._execute_clauseelement(self, multiparams, params)\n",
      "  File \"/lfs/local/0/jdunnmon/repos/anaconda3/envs/snorkel/lib/python3.6/site-packages/sqlalchemy/engine/base.py\", line 1060, in _execute_clauseelement\n",
      "    compiled_sql, distilled_params\n",
      "  File \"/lfs/local/0/jdunnmon/repos/anaconda3/envs/snorkel/lib/python3.6/site-packages/sqlalchemy/engine/base.py\", line 1200, in _execute_context\n",
      "    context)\n",
      "  File \"/lfs/local/0/jdunnmon/repos/anaconda3/envs/snorkel/lib/python3.6/site-packages/sqlalchemy/engine/base.py\", line 1413, in _handle_dbapi_exception\n",
      "    exc_info\n",
      "  File \"/lfs/local/0/jdunnmon/repos/anaconda3/envs/snorkel/lib/python3.6/site-packages/sqlalchemy/util/compat.py\", line 203, in raise_from_cause\n",
      "    reraise(type(exception), exception, tb=exc_tb, cause=cause)\n",
      "  File \"/lfs/local/0/jdunnmon/repos/anaconda3/envs/snorkel/lib/python3.6/site-packages/sqlalchemy/util/compat.py\", line 186, in reraise\n",
      "    raise value.with_traceback(tb)\n",
      "  File \"/lfs/local/0/jdunnmon/repos/anaconda3/envs/snorkel/lib/python3.6/site-packages/sqlalchemy/engine/base.py\", line 1170, in _execute_context\n",
      "    context)\n",
      "  File \"/lfs/local/0/jdunnmon/repos/anaconda3/envs/snorkel/lib/python3.6/site-packages/sqlalchemy/dialects/postgresql/psycopg2.py\", line 683, in do_executemany\n",
      "    cursor.executemany(statement, parameters)\n",
      "sqlalchemy.exc.IntegrityError: (psycopg2.IntegrityError) duplicate key value violates unique constraint \"location_location_id_key\"\n",
      "DETAIL:  Key (location_id)=(242946) already exists.\n",
      " [SQL: 'INSERT INTO location (id, location_id, location_cid) VALUES (%(id)s, %(location_id)s, %(location_cid)s)'] [parameters: ({'id': 66463, 'location_id': 239319, 'location_cid': None}, {'id': 66478, 'location_id': 239372, 'location_cid': None}, {'id': 66493, 'location_id': 239386, 'location_cid': None}, {'id': 66508, 'location_id': 239400, 'location_cid': None}, {'id': 66525, 'location_id': 239416, 'location_cid': None}, {'id': 66541, 'location_id': 239420, 'location_cid': None}, {'id': 66557, 'location_id': 239483, 'location_cid': None}, {'id': 66569, 'location_id': 239500, 'location_cid': None}  ... displaying 10 of 5821 total bound parameter sets ...  {'id': 158674, 'location_id': 330125, 'location_cid': None}, {'id': 158682, 'location_id': 330131, 'location_cid': None})] (Background on this error at: http://sqlalche.me/e/gkpj)\n",
      "Process CandidateExtractorUDF-30:\n",
      "Traceback (most recent call last):\n",
      "  File \"/lfs/local/0/jdunnmon/repos/anaconda3/envs/snorkel/lib/python3.6/site-packages/sqlalchemy/engine/base.py\", line 1170, in _execute_context\n",
      "    context)\n",
      "  File \"/lfs/local/0/jdunnmon/repos/anaconda3/envs/snorkel/lib/python3.6/site-packages/sqlalchemy/dialects/postgresql/psycopg2.py\", line 683, in do_executemany\n",
      "    cursor.executemany(statement, parameters)\n",
      "psycopg2.IntegrityError: duplicate key value violates unique constraint \"location_location_id_key\"\n",
      "DETAIL:  Key (location_id)=(245056) already exists.\n",
      "\n",
      "\n",
      "The above exception was the direct cause of the following exception:\n",
      "\n",
      "Traceback (most recent call last):\n",
      "  File \"/lfs/local/0/jdunnmon/repos/anaconda3/envs/snorkel/lib/python3.6/multiprocessing/process.py\", line 258, in _bootstrap\n",
      "    self.run()\n",
      "  File \"/lfs/raiders5/0/jdunnmon/repos/snorkel/snorkel/udf.py\", line 170, in run\n",
      "    self.session.commit()\n",
      "  File \"/lfs/local/0/jdunnmon/repos/anaconda3/envs/snorkel/lib/python3.6/site-packages/sqlalchemy/orm/session.py\", line 943, in commit\n",
      "    self.transaction.commit()\n",
      "  File \"/lfs/local/0/jdunnmon/repos/anaconda3/envs/snorkel/lib/python3.6/site-packages/sqlalchemy/orm/session.py\", line 467, in commit\n",
      "    self._prepare_impl()\n",
      "  File \"/lfs/local/0/jdunnmon/repos/anaconda3/envs/snorkel/lib/python3.6/site-packages/sqlalchemy/orm/session.py\", line 447, in _prepare_impl\n",
      "    self.session.flush()\n",
      "  File \"/lfs/local/0/jdunnmon/repos/anaconda3/envs/snorkel/lib/python3.6/site-packages/sqlalchemy/orm/session.py\", line 2254, in flush\n",
      "    self._flush(objects)\n",
      "  File \"/lfs/local/0/jdunnmon/repos/anaconda3/envs/snorkel/lib/python3.6/site-packages/sqlalchemy/orm/session.py\", line 2380, in _flush\n",
      "    transaction.rollback(_capture_exception=True)\n",
      "  File \"/lfs/local/0/jdunnmon/repos/anaconda3/envs/snorkel/lib/python3.6/site-packages/sqlalchemy/util/langhelpers.py\", line 66, in __exit__\n",
      "    compat.reraise(exc_type, exc_value, exc_tb)\n",
      "  File \"/lfs/local/0/jdunnmon/repos/anaconda3/envs/snorkel/lib/python3.6/site-packages/sqlalchemy/util/compat.py\", line 187, in reraise\n",
      "    raise value\n",
      "  File \"/lfs/local/0/jdunnmon/repos/anaconda3/envs/snorkel/lib/python3.6/site-packages/sqlalchemy/orm/session.py\", line 2344, in _flush\n",
      "    flush_context.execute()\n",
      "  File \"/lfs/local/0/jdunnmon/repos/anaconda3/envs/snorkel/lib/python3.6/site-packages/sqlalchemy/orm/unitofwork.py\", line 391, in execute\n",
      "    rec.execute(self)\n",
      "  File \"/lfs/local/0/jdunnmon/repos/anaconda3/envs/snorkel/lib/python3.6/site-packages/sqlalchemy/orm/unitofwork.py\", line 556, in execute\n",
      "    uow\n"
     ]
    },
    {
     "name": "stderr",
     "output_type": "stream",
     "text": [
      "  File \"/lfs/local/0/jdunnmon/repos/anaconda3/envs/snorkel/lib/python3.6/site-packages/sqlalchemy/orm/persistence.py\", line 181, in save_obj\n",
      "    mapper, table, insert)\n",
      "  File \"/lfs/local/0/jdunnmon/repos/anaconda3/envs/snorkel/lib/python3.6/site-packages/sqlalchemy/orm/persistence.py\", line 830, in _emit_insert_statements\n",
      "    execute(statement, multiparams)\n",
      "  File \"/lfs/local/0/jdunnmon/repos/anaconda3/envs/snorkel/lib/python3.6/site-packages/sqlalchemy/engine/base.py\", line 948, in execute\n",
      "    return meth(self, multiparams, params)\n",
      "  File \"/lfs/local/0/jdunnmon/repos/anaconda3/envs/snorkel/lib/python3.6/site-packages/sqlalchemy/sql/elements.py\", line 269, in _execute_on_connection\n",
      "    return connection._execute_clauseelement(self, multiparams, params)\n",
      "  File \"/lfs/local/0/jdunnmon/repos/anaconda3/envs/snorkel/lib/python3.6/site-packages/sqlalchemy/engine/base.py\", line 1060, in _execute_clauseelement\n",
      "    compiled_sql, distilled_params\n",
      "  File \"/lfs/local/0/jdunnmon/repos/anaconda3/envs/snorkel/lib/python3.6/site-packages/sqlalchemy/engine/base.py\", line 1200, in _execute_context\n",
      "    context)\n",
      "  File \"/lfs/local/0/jdunnmon/repos/anaconda3/envs/snorkel/lib/python3.6/site-packages/sqlalchemy/engine/base.py\", line 1413, in _handle_dbapi_exception\n",
      "    exc_info\n",
      "  File \"/lfs/local/0/jdunnmon/repos/anaconda3/envs/snorkel/lib/python3.6/site-packages/sqlalchemy/util/compat.py\", line 203, in raise_from_cause\n",
      "    reraise(type(exception), exception, tb=exc_tb, cause=cause)\n",
      "  File \"/lfs/local/0/jdunnmon/repos/anaconda3/envs/snorkel/lib/python3.6/site-packages/sqlalchemy/util/compat.py\", line 186, in reraise\n",
      "    raise value.with_traceback(tb)\n",
      "  File \"/lfs/local/0/jdunnmon/repos/anaconda3/envs/snorkel/lib/python3.6/site-packages/sqlalchemy/engine/base.py\", line 1170, in _execute_context\n",
      "    context)\n",
      "  File \"/lfs/local/0/jdunnmon/repos/anaconda3/envs/snorkel/lib/python3.6/site-packages/sqlalchemy/dialects/postgresql/psycopg2.py\", line 683, in do_executemany\n",
      "    cursor.executemany(statement, parameters)\n",
      "sqlalchemy.exc.IntegrityError: (psycopg2.IntegrityError) duplicate key value violates unique constraint \"location_location_id_key\"\n",
      "DETAIL:  Key (location_id)=(245056) already exists.\n",
      " [SQL: 'INSERT INTO location (id, location_id, location_cid) VALUES (%(id)s, %(location_id)s, %(location_cid)s)'] [parameters: ({'id': 66453, 'location_id': 239336, 'location_cid': None}, {'id': 66469, 'location_id': 239379, 'location_cid': None}, {'id': 66485, 'location_id': 239384, 'location_cid': None}, {'id': 66502, 'location_id': 239412, 'location_cid': None}, {'id': 66515, 'location_id': 239407, 'location_cid': None}, {'id': 66529, 'location_id': 239460, 'location_cid': None}, {'id': 66551, 'location_id': 239474, 'location_cid': None}, {'id': 66558, 'location_id': 239493, 'location_cid': None}  ... displaying 10 of 5722 total bound parameter sets ...  {'id': 157724, 'location_id': 330127, 'location_cid': None}, {'id': 157738, 'location_id': 330121, 'location_cid': None})] (Background on this error at: http://sqlalche.me/e/gkpj)\n",
      "Process CandidateExtractorUDF-28:\n",
      "Traceback (most recent call last):\n",
      "  File \"/lfs/local/0/jdunnmon/repos/anaconda3/envs/snorkel/lib/python3.6/site-packages/sqlalchemy/engine/base.py\", line 1170, in _execute_context\n",
      "    context)\n",
      "  File \"/lfs/local/0/jdunnmon/repos/anaconda3/envs/snorkel/lib/python3.6/site-packages/sqlalchemy/dialects/postgresql/psycopg2.py\", line 683, in do_executemany\n",
      "    cursor.executemany(statement, parameters)\n",
      "psycopg2.IntegrityError: duplicate key value violates unique constraint \"location_location_id_key\"\n",
      "DETAIL:  Key (location_id)=(241070) already exists.\n",
      "\n",
      "\n",
      "The above exception was the direct cause of the following exception:\n",
      "\n",
      "Traceback (most recent call last):\n",
      "  File \"/lfs/local/0/jdunnmon/repos/anaconda3/envs/snorkel/lib/python3.6/multiprocessing/process.py\", line 258, in _bootstrap\n",
      "    self.run()\n",
      "  File \"/lfs/raiders5/0/jdunnmon/repos/snorkel/snorkel/udf.py\", line 170, in run\n",
      "    self.session.commit()\n",
      "  File \"/lfs/local/0/jdunnmon/repos/anaconda3/envs/snorkel/lib/python3.6/site-packages/sqlalchemy/orm/session.py\", line 943, in commit\n",
      "    self.transaction.commit()\n",
      "  File \"/lfs/local/0/jdunnmon/repos/anaconda3/envs/snorkel/lib/python3.6/site-packages/sqlalchemy/orm/session.py\", line 467, in commit\n",
      "    self._prepare_impl()\n",
      "  File \"/lfs/local/0/jdunnmon/repos/anaconda3/envs/snorkel/lib/python3.6/site-packages/sqlalchemy/orm/session.py\", line 447, in _prepare_impl\n",
      "    self.session.flush()\n",
      "  File \"/lfs/local/0/jdunnmon/repos/anaconda3/envs/snorkel/lib/python3.6/site-packages/sqlalchemy/orm/session.py\", line 2254, in flush\n",
      "    self._flush(objects)\n",
      "  File \"/lfs/local/0/jdunnmon/repos/anaconda3/envs/snorkel/lib/python3.6/site-packages/sqlalchemy/orm/session.py\", line 2380, in _flush\n",
      "    transaction.rollback(_capture_exception=True)\n",
      "  File \"/lfs/local/0/jdunnmon/repos/anaconda3/envs/snorkel/lib/python3.6/site-packages/sqlalchemy/util/langhelpers.py\", line 66, in __exit__\n",
      "    compat.reraise(exc_type, exc_value, exc_tb)\n",
      "  File \"/lfs/local/0/jdunnmon/repos/anaconda3/envs/snorkel/lib/python3.6/site-packages/sqlalchemy/util/compat.py\", line 187, in reraise\n",
      "    raise value\n",
      "  File \"/lfs/local/0/jdunnmon/repos/anaconda3/envs/snorkel/lib/python3.6/site-packages/sqlalchemy/orm/session.py\", line 2344, in _flush\n",
      "    flush_context.execute()\n",
      "  File \"/lfs/local/0/jdunnmon/repos/anaconda3/envs/snorkel/lib/python3.6/site-packages/sqlalchemy/orm/unitofwork.py\", line 391, in execute\n",
      "    rec.execute(self)\n",
      "  File \"/lfs/local/0/jdunnmon/repos/anaconda3/envs/snorkel/lib/python3.6/site-packages/sqlalchemy/orm/unitofwork.py\", line 556, in execute\n",
      "    uow\n",
      "  File \"/lfs/local/0/jdunnmon/repos/anaconda3/envs/snorkel/lib/python3.6/site-packages/sqlalchemy/orm/persistence.py\", line 181, in save_obj\n",
      "    mapper, table, insert)\n",
      "  File \"/lfs/local/0/jdunnmon/repos/anaconda3/envs/snorkel/lib/python3.6/site-packages/sqlalchemy/orm/persistence.py\", line 830, in _emit_insert_statements\n",
      "    execute(statement, multiparams)\n",
      "  File \"/lfs/local/0/jdunnmon/repos/anaconda3/envs/snorkel/lib/python3.6/site-packages/sqlalchemy/engine/base.py\", line 948, in execute\n",
      "    return meth(self, multiparams, params)\n",
      "  File \"/lfs/local/0/jdunnmon/repos/anaconda3/envs/snorkel/lib/python3.6/site-packages/sqlalchemy/sql/elements.py\", line 269, in _execute_on_connection\n",
      "    return connection._execute_clauseelement(self, multiparams, params)\n",
      "  File \"/lfs/local/0/jdunnmon/repos/anaconda3/envs/snorkel/lib/python3.6/site-packages/sqlalchemy/engine/base.py\", line 1060, in _execute_clauseelement\n",
      "    compiled_sql, distilled_params\n",
      "  File \"/lfs/local/0/jdunnmon/repos/anaconda3/envs/snorkel/lib/python3.6/site-packages/sqlalchemy/engine/base.py\", line 1200, in _execute_context\n",
      "    context)\n",
      "  File \"/lfs/local/0/jdunnmon/repos/anaconda3/envs/snorkel/lib/python3.6/site-packages/sqlalchemy/engine/base.py\", line 1413, in _handle_dbapi_exception\n",
      "    exc_info\n",
      "  File \"/lfs/local/0/jdunnmon/repos/anaconda3/envs/snorkel/lib/python3.6/site-packages/sqlalchemy/util/compat.py\", line 203, in raise_from_cause\n",
      "    reraise(type(exception), exception, tb=exc_tb, cause=cause)\n",
      "  File \"/lfs/local/0/jdunnmon/repos/anaconda3/envs/snorkel/lib/python3.6/site-packages/sqlalchemy/util/compat.py\", line 186, in reraise\n",
      "    raise value.with_traceback(tb)\n",
      "  File \"/lfs/local/0/jdunnmon/repos/anaconda3/envs/snorkel/lib/python3.6/site-packages/sqlalchemy/engine/base.py\", line 1170, in _execute_context\n",
      "    context)\n",
      "  File \"/lfs/local/0/jdunnmon/repos/anaconda3/envs/snorkel/lib/python3.6/site-packages/sqlalchemy/dialects/postgresql/psycopg2.py\", line 683, in do_executemany\n",
      "    cursor.executemany(statement, parameters)\n",
      "sqlalchemy.exc.IntegrityError: (psycopg2.IntegrityError) duplicate key value violates unique constraint \"location_location_id_key\"\n",
      "DETAIL:  Key (location_id)=(241070) already exists.\n",
      " [SQL: 'INSERT INTO location (id, location_id, location_cid) VALUES (%(id)s, %(location_id)s, %(location_cid)s)'] [parameters: ({'id': 66503, 'location_id': 239304, 'location_cid': None}, {'id': 66519, 'location_id': 239346, 'location_cid': None}, {'id': 66528, 'location_id': 239341, 'location_cid': None}, {'id': 66546, 'location_id': 239359, 'location_cid': None}, {'id': 66565, 'location_id': 239362, 'location_cid': None}, {'id': 66581, 'location_id': 239373, 'location_cid': None}, {'id': 66597, 'location_id': 239399, 'location_cid': None}, {'id': 66612, 'location_id': 239421, 'location_cid': None}  ... displaying 10 of 5966 total bound parameter sets ...  {'id': 159114, 'location_id': 330062, 'location_cid': None}, {'id': 159115, 'location_id': 330072, 'location_cid': None})] (Background on this error at: http://sqlalche.me/e/gkpj)\n"
     ]
    },
    {
     "name": "stderr",
     "output_type": "stream",
     "text": [
      "Process CandidateExtractorUDF-24:\n",
      "Traceback (most recent call last):\n",
      "  File \"/lfs/local/0/jdunnmon/repos/anaconda3/envs/snorkel/lib/python3.6/site-packages/sqlalchemy/engine/base.py\", line 1170, in _execute_context\n",
      "    context)\n",
      "  File \"/lfs/local/0/jdunnmon/repos/anaconda3/envs/snorkel/lib/python3.6/site-packages/sqlalchemy/dialects/postgresql/psycopg2.py\", line 683, in do_executemany\n",
      "    cursor.executemany(statement, parameters)\n",
      "psycopg2.IntegrityError: duplicate key value violates unique constraint \"location_location_id_key\"\n",
      "DETAIL:  Key (location_id)=(290934) already exists.\n",
      "\n",
      "\n",
      "The above exception was the direct cause of the following exception:\n",
      "\n",
      "Traceback (most recent call last):\n",
      "  File \"/lfs/local/0/jdunnmon/repos/anaconda3/envs/snorkel/lib/python3.6/multiprocessing/process.py\", line 258, in _bootstrap\n",
      "    self.run()\n",
      "  File \"/lfs/raiders5/0/jdunnmon/repos/snorkel/snorkel/udf.py\", line 170, in run\n",
      "    self.session.commit()\n",
      "  File \"/lfs/local/0/jdunnmon/repos/anaconda3/envs/snorkel/lib/python3.6/site-packages/sqlalchemy/orm/session.py\", line 943, in commit\n",
      "    self.transaction.commit()\n",
      "  File \"/lfs/local/0/jdunnmon/repos/anaconda3/envs/snorkel/lib/python3.6/site-packages/sqlalchemy/orm/session.py\", line 467, in commit\n",
      "    self._prepare_impl()\n",
      "  File \"/lfs/local/0/jdunnmon/repos/anaconda3/envs/snorkel/lib/python3.6/site-packages/sqlalchemy/orm/session.py\", line 447, in _prepare_impl\n",
      "    self.session.flush()\n",
      "  File \"/lfs/local/0/jdunnmon/repos/anaconda3/envs/snorkel/lib/python3.6/site-packages/sqlalchemy/orm/session.py\", line 2254, in flush\n",
      "    self._flush(objects)\n",
      "  File \"/lfs/local/0/jdunnmon/repos/anaconda3/envs/snorkel/lib/python3.6/site-packages/sqlalchemy/orm/session.py\", line 2380, in _flush\n",
      "    transaction.rollback(_capture_exception=True)\n",
      "  File \"/lfs/local/0/jdunnmon/repos/anaconda3/envs/snorkel/lib/python3.6/site-packages/sqlalchemy/util/langhelpers.py\", line 66, in __exit__\n",
      "    compat.reraise(exc_type, exc_value, exc_tb)\n",
      "  File \"/lfs/local/0/jdunnmon/repos/anaconda3/envs/snorkel/lib/python3.6/site-packages/sqlalchemy/util/compat.py\", line 187, in reraise\n",
      "    raise value\n",
      "  File \"/lfs/local/0/jdunnmon/repos/anaconda3/envs/snorkel/lib/python3.6/site-packages/sqlalchemy/orm/session.py\", line 2344, in _flush\n",
      "    flush_context.execute()\n",
      "  File \"/lfs/local/0/jdunnmon/repos/anaconda3/envs/snorkel/lib/python3.6/site-packages/sqlalchemy/orm/unitofwork.py\", line 391, in execute\n",
      "    rec.execute(self)\n",
      "  File \"/lfs/local/0/jdunnmon/repos/anaconda3/envs/snorkel/lib/python3.6/site-packages/sqlalchemy/orm/unitofwork.py\", line 556, in execute\n",
      "    uow\n",
      "  File \"/lfs/local/0/jdunnmon/repos/anaconda3/envs/snorkel/lib/python3.6/site-packages/sqlalchemy/orm/persistence.py\", line 181, in save_obj\n",
      "    mapper, table, insert)\n",
      "  File \"/lfs/local/0/jdunnmon/repos/anaconda3/envs/snorkel/lib/python3.6/site-packages/sqlalchemy/orm/persistence.py\", line 830, in _emit_insert_statements\n",
      "    execute(statement, multiparams)\n",
      "  File \"/lfs/local/0/jdunnmon/repos/anaconda3/envs/snorkel/lib/python3.6/site-packages/sqlalchemy/engine/base.py\", line 948, in execute\n",
      "    return meth(self, multiparams, params)\n",
      "  File \"/lfs/local/0/jdunnmon/repos/anaconda3/envs/snorkel/lib/python3.6/site-packages/sqlalchemy/sql/elements.py\", line 269, in _execute_on_connection\n",
      "    return connection._execute_clauseelement(self, multiparams, params)\n",
      "  File \"/lfs/local/0/jdunnmon/repos/anaconda3/envs/snorkel/lib/python3.6/site-packages/sqlalchemy/engine/base.py\", line 1060, in _execute_clauseelement\n",
      "    compiled_sql, distilled_params\n",
      "  File \"/lfs/local/0/jdunnmon/repos/anaconda3/envs/snorkel/lib/python3.6/site-packages/sqlalchemy/engine/base.py\", line 1200, in _execute_context\n",
      "    context)\n",
      "  File \"/lfs/local/0/jdunnmon/repos/anaconda3/envs/snorkel/lib/python3.6/site-packages/sqlalchemy/engine/base.py\", line 1413, in _handle_dbapi_exception\n",
      "    exc_info\n",
      "  File \"/lfs/local/0/jdunnmon/repos/anaconda3/envs/snorkel/lib/python3.6/site-packages/sqlalchemy/util/compat.py\", line 203, in raise_from_cause\n",
      "    reraise(type(exception), exception, tb=exc_tb, cause=cause)\n",
      "  File \"/lfs/local/0/jdunnmon/repos/anaconda3/envs/snorkel/lib/python3.6/site-packages/sqlalchemy/util/compat.py\", line 186, in reraise\n",
      "    raise value.with_traceback(tb)\n",
      "  File \"/lfs/local/0/jdunnmon/repos/anaconda3/envs/snorkel/lib/python3.6/site-packages/sqlalchemy/engine/base.py\", line 1170, in _execute_context\n",
      "    context)\n",
      "  File \"/lfs/local/0/jdunnmon/repos/anaconda3/envs/snorkel/lib/python3.6/site-packages/sqlalchemy/dialects/postgresql/psycopg2.py\", line 683, in do_executemany\n",
      "    cursor.executemany(statement, parameters)\n",
      "sqlalchemy.exc.IntegrityError: (psycopg2.IntegrityError) duplicate key value violates unique constraint \"location_location_id_key\"\n",
      "DETAIL:  Key (location_id)=(290934) already exists.\n",
      " [SQL: 'INSERT INTO location (id, location_id, location_cid) VALUES (%(id)s, %(location_id)s, %(location_cid)s)'] [parameters: ({'id': 66448, 'location_id': 239315, 'location_cid': None}, {'id': 66462, 'location_id': 239306, 'location_cid': None}, {'id': 66475, 'location_id': 239339, 'location_cid': None}, {'id': 66492, 'location_id': 239342, 'location_cid': None}, {'id': 66504, 'location_id': 239347, 'location_cid': None}, {'id': 66522, 'location_id': 239364, 'location_cid': None}, {'id': 66539, 'location_id': 239361, 'location_cid': None}, {'id': 66554, 'location_id': 239385, 'location_cid': None}  ... displaying 10 of 5638 total bound parameter sets ...  {'id': 156570, 'location_id': 330036, 'location_cid': None}, {'id': 156593, 'location_id': 330093, 'location_cid': None})] (Background on this error at: http://sqlalche.me/e/gkpj)\n"
     ]
    },
    {
     "name": "stdout",
     "output_type": "stream",
     "text": [
      "CPU times: user 27.9 s, sys: 4.06 s, total: 32 s\n",
      "Wall time: 4min 6s\n"
     ]
    }
   ],
   "source": [
    "# Applying candidate extractor to each split\n",
    "%time cand_extractor.apply(sents, split=0, parallelism=16)\n",
    "#print(\"Number of candidates:\", session.query(candidate_class).filter(candidate_class.split == 0).count())"
   ]
  },
  {
   "cell_type": "markdown",
   "metadata": {},
   "source": [
    "Getting candidates for evaluation"
   ]
  },
  {
   "cell_type": "code",
   "execution_count": 9,
   "metadata": {},
   "outputs": [
    {
     "name": "stdout",
     "output_type": "stream",
     "text": [
      "Loaded 4733 candidates...\n"
     ]
    }
   ],
   "source": [
    "# Split to pull eval candidates from\n",
    "eval_split = 0\n",
    "\n",
    "# Executing query for eval candidates\n",
    "eval_cands = session.query(candidate_class).filter(candidate_class.split == eval_split).order_by(candidate_class.id).all()\n",
    "print(f'Loaded {len(eval_cands)} candidates...')"
   ]
  },
  {
   "cell_type": "markdown",
   "metadata": {},
   "source": [
    "Loading trained discriminative model"
   ]
  },
  {
   "cell_type": "code",
   "execution_count": 21,
   "metadata": {},
   "outputs": [
    {
     "name": "stdout",
     "output_type": "stream",
     "text": [
      "===============================================\n",
      "Number of learning epochs:      5\n",
      "Learning rate:                  1e-05\n",
      "Use attention:                  False\n",
      "LSTM hidden dimension:          128\n",
      "Dropout:                        0.5\n",
      "Checkpoint Patience:            2\n",
      "Batch size:                     128\n",
      "Rebalance:                      0.5\n",
      "Load pre-trained embedding:     False\n",
      "Host device:                    gpu\n",
      "Word embedding size:            300\n",
      "Word embedding:                 None\n",
      "===============================================\n",
      "[LSTM] Loaded model <location_lstm>, only_param=False\n"
     ]
    }
   ],
   "source": [
    "from dm_utils import LSTM\n",
    "\n",
    "# defining model\n",
    "lstm = LSTM(n_threads=parallelism)\n",
    "\n",
    "# defining saved weights directory and name\n",
    "\n",
    "model_name = 'location_lstm' # this was provided when the model was saved!\n",
    "save_dir = 'checkpoints' # this was provided when the model was saved!\n",
    "\n",
    "# loading\n",
    "lstm.load(model_name=model_name, save_dir=save_dir, verbose=True)"
   ]
  },
  {
   "cell_type": "markdown",
   "metadata": {},
   "source": [
    "Getting and plotting discriminative model marginals."
   ]
  },
  {
   "cell_type": "code",
   "execution_count": 23,
   "metadata": {},
   "outputs": [
    {
     "name": "stderr",
     "output_type": "stream",
     "text": [
      "../utils/dm_utils.py:133: UserWarning: RNN module weights are not part of single contiguous chunk of memory. This means they need to be compacted at every call, possibly greatly increasing memory usage. To compact weights again call flatten_parameters().\n",
      "  output_word, state_word = self.word_lstm(x_emb, state_word)\n"
     ]
    },
    {
     "name": "stdout",
     "output_type": "stream",
     "text": [
      "CPU times: user 10 s, sys: 552 ms, total: 10.6 s\n",
      "Wall time: 12.4 s\n"
     ]
    },
    {
     "data": {
      "image/png": "iVBORw0KGgoAAAANSUhEUgAAAYAAAAD8CAYAAAB+UHOxAAAABHNCSVQICAgIfAhkiAAAAAlwSFlzAAALEgAACxIB0t1+/AAAADl0RVh0U29mdHdhcmUAbWF0cGxvdGxpYiB2ZXJzaW9uIDIuMi4yLCBodHRwOi8vbWF0cGxvdGxpYi5vcmcvhp/UCwAAEd9JREFUeJzt3X+s3Xddx/Hnyw6mQXSduyOzK3Zil9AZ3eBmLCEaFN26Ge2IoJ0JVIJWky5AJMZhTEaGJNOoGOKcDtdYjNgsqFmF6iwTJJhMdgdzrJvLLttkly5bpRMk6KT17R/nc+Wsuz/O/X17P89HcnK+3/f38z3n8+m3va9+v5/vOTdVhSSpP9+y1h2QJK0NA0CSOmUASFKnDABJ6pQBIEmdMgAkqVMGgCR1ygCQpE4ZAJLUqbPma5DkW4FPAWe39h+pqhuTXAQcBM4FPgu8uar+J8nZwIeAVwNfBn62qp5or/Vu4G3AKeDtVXXXXO993nnn1bZt2xY5NEnq03333ffvVTU2X7t5AwB4DvjRqvpakhcBn07yt8CvAO+vqoNJ/ojBD/Zb2/OzVfV9SXYDvwX8bJIdwG7gEuC7gY8nubiqTs32xtu2bWNiYmKELkqSpiX5t1HazXsJqAa+1lZf1B4F/CjwkVY/AFzblne1ddr21ydJqx+squeq6nFgErh8lE5KkpbfSHMASTYluR94BjgCfAH4j6o62ZpMAVva8hbgSYC2/SvAdw3XZ9hn+L32JplIMnH8+PGFj0iSNJKRAqCqTlXVpcCFDP7X/sqZmrXnzLJttvrp73VbVY1X1fjY2LyXsCRJi7Sgu4Cq6j+ATwJXAOckmZ5DuBA41pangK0Abft3AieG6zPsI0laZfMGQJKxJOe05W8Dfgx4GPgE8MbWbA9wZ1s+1NZp2/+hBr904BCwO8nZ7Q6i7cBnlmsgkqSFGeUuoAuAA0k2MQiMO6rqo0keAg4m+U3gc8Dtrf3twJ8lmWTwP//dAFV1NMkdwEPASWDfXHcASZJWVtbzbwQbHx8vbwOVpIVJcl9Vjc/Xzk8CS1KnDABJ6tQocwCSltm2Gz626H2fuPknlrEn6plnAJLUKQNAkjplAEhSpwwASeqUASBJnTIAJKlTBoAkdcoAkKROGQCS1CkDQJI6ZQBIUqcMAEnqlAEgSZ0yACSpUwaAJHXKAJCkThkAktQpA0CSOmUASFKnDABJ6pQBIEmdMgAkqVMGgCR1ygCQpE7NGwBJtib5RJKHkxxN8o5Wf0+SLyW5vz2uGdrn3UkmkzyS5Kqh+s5Wm0xyw8oMSZI0irNGaHMSeFdVfTbJS4H7khxp295fVb8z3DjJDmA3cAnw3cDHk1zcNt8C/DgwBdyb5FBVPbQcA5EkLcy8AVBVTwFPteX/TPIwsGWOXXYBB6vqOeDxJJPA5W3bZFU9BpDkYGtrAEjSGljQHECSbcBlwD+30vVJHkiyP8nmVtsCPDm021SrzVY//T32JplIMnH8+PGFdE+StAAjB0CSbwf+EnhnVX0VuBV4BXApgzOE351uOsPuNUf9+YWq26pqvKrGx8bGRu2eJGmBRpkDIMmLGPzw//Oq+iuAqnp6aPsHgY+21Slg69DuFwLH2vJsdUnSKhvlLqAAtwMPV9XvDdUvGGr2BuDBtnwI2J3k7CQXAduBzwD3AtuTXJTkxQwmig8tzzAkSQs1yhnAa4E3A59Pcn+r/TpwXZJLGVzGeQL4JYCqOprkDgaTuyeBfVV1CiDJ9cBdwCZgf1UdXcaxSJIWYJS7gD7NzNfvD8+xz/uA981QPzzXfpKk1eMngSWpUwaAJHXKAJCkThkAktQpA0CSOmUASFKnDABJ6pQBIEmdMgAkqVMGgCR1ygCQpE4ZAJLUKQNAkjplAEhSpwwASeqUASBJnTIAJKlTBoAkdcoAkKROGQCS1CkDQJI6ZQBIUqcMAEnqlAEgSZ0yACSpUwaAJHVq3gBIsjXJJ5I8nORokne0+rlJjiR5tD1vbvUk+UCSySQPJHnV0Gvtae0fTbJn5YYlSZrPKGcAJ4F3VdUrgSuAfUl2ADcAd1fVduDutg5wNbC9PfYCt8IgMIAbgdcAlwM3ToeGJGn1zRsAVfVUVX22Lf8n8DCwBdgFHGjNDgDXtuVdwIdq4B7gnCQXAFcBR6rqRFU9CxwBdi7raCRJI1vQHECSbcBlwD8DL6uqp2AQEsD5rdkW4Mmh3aZabba6JGkNjBwASb4d+EvgnVX11bmazlCrOeqnv8/eJBNJJo4fPz5q9yRJCzRSACR5EYMf/n9eVX/Vyk+3Szu052dafQrYOrT7hcCxOerPU1W3VdV4VY2PjY0tZCySpAUY5S6gALcDD1fV7w1tOgRM38mzB7hzqP6WdjfQFcBX2iWiu4Ark2xuk79XtpokaQ2cNUKb1wJvBj6f5P5W+3XgZuCOJG8Dvgi8qW07DFwDTAJfB94KUFUnkrwXuLe1u6mqTizLKCRJCzZvAFTVp5n5+j3A62doX8C+WV5rP7B/IR2UJK0MPwksSZ0yACSpUwaAJHXKAJCkThkAktQpA0CSOmUASFKnDABJ6pQBIEmdMgAkqVMGgCR1ygCQpE4ZAJLUKQNAkjplAEhSpwwASeqUASBJnTIAJKlTBoAkdcoAkKROGQCS1CkDQJI6ZQBIUqcMAEnqlAEgSZ0yACSpUwaAJHVq3gBIsj/JM0keHKq9J8mXktzfHtcMbXt3kskkjyS5aqi+s9Umk9yw/EORJC3EKGcAfwrsnKH+/qq6tD0OAyTZAewGLmn7/GGSTUk2AbcAVwM7gOtaW0nSGjlrvgZV9akk20Z8vV3Awap6Dng8ySRweds2WVWPASQ52No+tOAeS5KWxVLmAK5P8kC7RLS51bYATw61mWq12eqSpDWy2AC4FXgFcCnwFPC7rZ4Z2tYc9RdIsjfJRJKJ48ePL7J7kqT5LCoAqurpqjpVVf8LfJBvXuaZArYONb0QODZHfabXvq2qxqtqfGxsbDHdkySNYFEBkOSCodU3ANN3CB0Cdic5O8lFwHbgM8C9wPYkFyV5MYOJ4kOL77YkaanmnQRO8hfA64DzkkwBNwKvS3Ipg8s4TwC/BFBVR5PcwWBy9ySwr6pOtde5HrgL2ATsr6qjyz4aSdLIRrkL6LoZyrfP0f59wPtmqB8GDi+od5KkFeMngSWpUwaAJHXKAJCkThkAktQpA0CSOmUASFKnDABJ6pQBIEmdMgAkqVMGgCR1ygCQpE4ZAJLUKQNAkjplAEhSpwwASeqUASBJnTIAJKlTBoAkdcoAkKROGQCS1CkDQJI6ZQBIUqcMAEnqlAEgSZ0yACSpUwaAJHXKAJCkTs0bAEn2J3kmyYNDtXOTHEnyaHve3OpJ8oEkk0keSPKqoX32tPaPJtmzMsORJI1qlDOAPwV2nla7Abi7qrYDd7d1gKuB7e2xF7gVBoEB3Ai8BrgcuHE6NCRJa2PeAKiqTwEnTivvAg605QPAtUP1D9XAPcA5SS4ArgKOVNWJqnoWOMILQ0WStIoWOwfwsqp6CqA9n9/qW4Anh9pNtdps9RdIsjfJRJKJ48ePL7J7kqT5LPckcGao1Rz1Fxarbquq8aoaHxsbW9bOSZK+abEB8HS7tEN7fqbVp4CtQ+0uBI7NUZckrZHFBsAhYPpOnj3AnUP1t7S7ga4AvtIuEd0FXJlkc5v8vbLVJElr5Kz5GiT5C+B1wHlJphjczXMzcEeStwFfBN7Umh8GrgEmga8DbwWoqhNJ3gvc29rdVFWnTyxLklbRvAFQVdfNsun1M7QtYN8sr7Mf2L+g3kmSVoyfBJakThkAktQpA0CSOmUASFKnDABJ6pQBIEmdMgAkqVMGgCR1ygCQpE4ZAJLUKQNAkjplAEhSpwwASeqUASBJnTIAJKlTBoAkdcoAkKROGQCS1CkDQJI6ZQBIUqcMAEnqlAEgSZ0yACSpUwaAJHXKAJCkThkAktSpJQVAkieSfD7J/UkmWu3cJEeSPNqeN7d6knwgyWSSB5K8ajkGIElanOU4A/iRqrq0qsbb+g3A3VW1Hbi7rQNcDWxvj73Arcvw3pKkRVqJS0C7gANt+QBw7VD9QzVwD3BOkgtW4P0lSSNYagAU8PdJ7kuyt9VeVlVPAbTn81t9C/Dk0L5TrSZJWgNnLXH/11bVsSTnA0eS/OscbTNDrV7QaBAkewFe/vKXL7F7kqTZLOkMoKqOtedngL8GLgeenr60056fac2ngK1Du18IHJvhNW+rqvGqGh8bG1tK9yRJc1h0ACR5SZKXTi8DVwIPAoeAPa3ZHuDOtnwIeEu7G+gK4CvTl4okSatvKZeAXgb8dZLp1/lwVf1dknuBO5K8Dfgi8KbW/jBwDTAJfB146xLeW5K0RIsOgKp6DPjBGepfBl4/Q72AfYt9P0nS8vKTwJLUKQNAkjplAEhSpwwASeqUASBJnVrqJ4Glbm274WNr3QVpSTwDkKROGQCS1CkDQJI6ZQBIUqecBJbOMEudfH7i5p9Ypp7oTOcZgCR1ygCQpE4ZAJLUKQNAkjplAEhSp7wLSGtuKXe1LPWOFr/OQT3zDECSOmUASFKnvASkM5qXcKTFMwCkzqzlnIvWFy8BSVKnDABJ6pSXgCSNzMtHG4sBoP/nP26pLwbABrNWd8V4N4505nEOQJI6teoBkGRnkkeSTCa5YbXfX5I0sKoBkGQTcAtwNbADuC7JjtXsgyRpYLXPAC4HJqvqsar6H+AgsGuV+yBJYvUngbcATw6tTwGvWak3W6u7WpwQlV7oTP13sZHvcFvtAMgMtXpeg2QvsLetfi3JI6e1Pw/49xXo2/Pkt1b6HWa1KuNbI47tzNT12NbwZ8FSfM8ojVY7AKaArUPrFwLHhhtU1W3AbbO9QJKJqhpfme6tvY08Psd2ZnJsG9dqzwHcC2xPclGSFwO7gUOr3AdJEqt8BlBVJ5NcD9wFbAL2V9XR1eyDJGlg1T8JXFWHgcNLeIlZLw9tEBt5fI7tzOTYNqhU1fytJEkbjl8FIUmdWlcBMN/XRCT55SSfT3J/kk9Pf4o4ybYk/9Xq9yf5o9Xv/dxG/QqMJG9MUknGh2rvbvs9kuSq1enx6BY7to1w3JL8fJLjQ2P4haFte5I82h57Vrfn81vi2E4N1dfljRyj/L1M8jNJHkpyNMmHh+rr+tgtm6paFw8Gk8JfAL4XeDHwL8CO09p8x9DyTwF/15a3AQ+u9RiWMrbW7qXAp4B7gPFW29Hanw1c1F5n01qPaZnGdsYfN+DngT+YYd9zgcfa8+a2vHmtx7QcY2vbvrbWY1iG8W0HPjd9XIDzz4Rjt5yP9XQGMO/XRFTVV4dWX8JpHyJbx0b9Coz3Ar8N/PdQbRdwsKqeq6rHgcn2euvFUsa23i3lq0uuAo5U1YmqehY4AuxcoX4uxkb/WpZRxveLwC3t+FBVz7T6ej92y2Y9BcBMXxOx5fRGSfYl+QKDHyZvH9p0UZLPJfnHJD+0sl1dsHnHluQyYGtVfXSh+66xpYwNzvDj1vx0kgeSfCTJ9Acdz/jj1sw0NoBvTTKR5J4k165oTxdnlPFdDFyc5J/aOHYuYN8NYT0FwLxfEwFQVbdU1SuAXwN+o5WfAl5eVZcBvwJ8OMl3rFhPF27OsSX5FuD9wLsWuu86sJSxndHHrfkbYFtV/QDwceDAAvZdS0sZGwyO2zjwc8DvJ3nFynRz0UYZ31kMLgO9DrgO+JMk54y474awngJg3q+JOM1B4FqAdnnky235PgbX/i5eoX4uxnxjeynw/cAnkzwBXAEcapOlC/1zWW2LHtsGOG5U1Zer6rm2+kHg1aPuu8aWMjaq6lh7fgz4JHDZSnZ2EUb5858C7qyqb7TLq48wCIT1fuyWz1pPQkw/GKTxYwwmOqcnbS45rc32oeWfBCba8hhtYpTBpM+XgHPXekwLGdtp7T/JNydKL+H5k8CPsb4mgZcytjP+uAEXDC2/AbinLZ8LPM5gEnFzW94oY9sMnN2WzwMeZYaJ/zNgfDuBA0PjeBL4rvV+7JbzsW5+J3DN8jURSW5i8IP+EHB9kh8DvgE8C0zfnvXDwE1JTgKngF+uqhOrP4qZjTi22fY9muQO4CHgJLCvqk6tSsdHsJSxsTGO29uT/BSDY3OCwZ0zVNWJJO9l8P1XADdtlLEBrwT+OMn/MriKcHNVPbTqg5jDiOO7C7gyyUMM/v79arUz0vV87JaTnwSWpE6tpzkASdIqMgAkqVMGgCR1ygCQpE4ZAJLUKQNAkjplAEhSpwwASerU/wFbr9eN35N1lwAAAABJRU5ErkJggg==\n",
      "text/plain": [
       "<Figure size 432x288 with 1 Axes>"
      ]
     },
     "metadata": {},
     "output_type": "display_data"
    }
   ],
   "source": [
    "import matplotlib.pyplot as plt\n",
    "\n",
    "%time eval_marginals = lstm.marginals(eval_cands)\n",
    "# Plotting eval marginals\n",
    "plt.hist(eval_marginals, bins=20)\n",
    "plt.show()"
   ]
  },
  {
   "cell_type": "markdown",
   "metadata": {},
   "source": [
    "Generating extractions from discriminative model marginals"
   ]
  },
  {
   "cell_type": "code",
   "execution_count": 24,
   "metadata": {},
   "outputs": [],
   "source": [
    "from gm_utils import create_extractions_dict\n",
    "\n",
    "# Enter googlemaps api key to get geocodes, leave blank to just use extracted locations\n",
    "geocode_key = None\n",
    "# geocode_key = 'AIzaSyBlLyOaasYMgMxFGUh2jJyxIG0_pZFF_jM'\n",
    "\n",
    "doc_extractions = create_extractions_dict(session, eval_cands, eval_marginals, extractions=[extraction_type],\n",
    "                                          dummy=False, geocode_key=geocode_key)\n",
    "\n",
    "# Uncomment to inspecting extractions dict to check format\n",
    "#doc_extractions"
   ]
  },
  {
   "cell_type": "markdown",
   "metadata": {},
   "source": [
    "Saving extractions to json file"
   ]
  },
  {
   "cell_type": "code",
   "execution_count": 26,
   "metadata": {},
   "outputs": [],
   "source": [
    "import json\n",
    "\n",
    "# Setting filename\n",
    "out_filename = \"loc_ext_test_discriminative_eval_10K.jsonl\"\n",
    "\n",
    "# Saving file to jsonl in extractions format\n",
    "with open(out_filename, 'w') as outfile:\n",
    "    for k,v in doc_extractions.items():\n",
    "        v['id'] = k\n",
    "        print(json.dumps(v), file=outfile)"
   ]
  },
  {
   "cell_type": "code",
   "execution_count": 34,
   "metadata": {},
   "outputs": [
    {
     "data": {
      "text/plain": [
       "{'url': \"b'http://www.naughtyreviews.com/companions/vanessa-rio-grande-valley-latin-female'\",\n",
       " 'location': [['Extracted String: rio grande',\n",
       "   ('Rio Grande', '23', 'BR', 187838, -32.035, -52.09861),\n",
       "   ('Río Grande', '23', 'AR', 52681, -53.78769, -67.70946),\n",
       "   ('Río Grande', '32', 'MX', 29841, 23.82647, -103.03034),\n",
       "   ('Río Grande', '18', 'DO', 20154, 19.66667, -70.76667)],\n",
       "  ['Extracted String: dating', ('Ōmachi', '26', 'JP', 30599, 36.5, 137.86667)],\n",
       "  ['Extracted String: name', ('Namur', 'WAL', 'BE', 106284, 50.4669, 4.86746)],\n",
       "  ['Extracted String: most', ('Most', '89', 'CZ', 67905, 50.50301, 13.63617)],\n",
       "  ['Extracted String: makes',\n",
       "   ('Marquette', 'MI', 'US', 21297, 46.54354, -87.39542)],\n",
       "  ['Extracted String: peer', ('Peer', 'VLG', 'BE', 15551, 51.1303, 5.45952)],\n",
       "  ['Extracted String: date',\n",
       "   ('Date', '12', 'JP', 35301, 42.46806, 140.86806)]],\n",
       " 'id': \"b'B2F9273FE35A2056217BBCB319C9F97CCC91CE0B6023578558DEC8B6A7683A73'\"}"
      ]
     },
     "execution_count": 34,
     "metadata": {},
     "output_type": "execute_result"
    }
   ],
   "source": [
    "doc_extractions[list(doc_extractions.keys())[2]]"
   ]
  },
  {
   "cell_type": "code",
   "execution_count": 48,
   "metadata": {},
   "outputs": [],
   "source": [
    "dc = session.query(Document).filter(Document.name=='376EBC69D1761B72FFC77ACA59593DD5B8E9E76A441DD1B5B0B056EC9A57D3D3').all()"
   ]
  },
  {
   "cell_type": "code",
   "execution_count": 49,
   "metadata": {},
   "outputs": [
    {
     "data": {
      "text/plain": [
       "[]"
      ]
     },
     "execution_count": 49,
     "metadata": {},
     "output_type": "execute_result"
    }
   ],
   "source": [
    "dc"
   ]
  },
  {
   "cell_type": "code",
   "execution_count": 44,
   "metadata": {},
   "outputs": [],
   "source": [
    "a = docs[1]"
   ]
  },
  {
   "cell_type": "code",
   "execution_count": 45,
   "metadata": {},
   "outputs": [
    {
     "data": {
      "text/plain": [
       "Document b'376EBC69D1761B72FFC77ACA59593DD5B8E9E76A441DD1B5B0B056EC9A57D3D3'"
      ]
     },
     "execution_count": 45,
     "metadata": {},
     "output_type": "execute_result"
    }
   ],
   "source": [
    "a"
   ]
  },
  {
   "cell_type": "code",
   "execution_count": 46,
   "metadata": {},
   "outputs": [
    {
     "data": {
      "text/plain": [
       "\"b'376EBC69D1761B72FFC77ACA59593DD5B8E9E76A441DD1B5B0B056EC9A57D3D3'::document:0:0\""
      ]
     },
     "execution_count": 46,
     "metadata": {},
     "output_type": "execute_result"
    }
   ],
   "source": [
    "a.name"
   ]
  },
  {
   "cell_type": "code",
   "execution_count": 47,
   "metadata": {},
   "outputs": [
    {
     "data": {
      "text/plain": [
       "\"b'376EBC69D1761B72FFC77ACA59593DD5B8E9E76A441DD1B5B0B056EC9A57D3D3'\""
      ]
     },
     "execution_count": 47,
     "metadata": {},
     "output_type": "execute_result"
    }
   ],
   "source": [
    "a.name"
   ]
  },
  {
   "cell_type": "code",
   "execution_count": null,
   "metadata": {},
   "outputs": [],
   "source": []
  }
 ],
 "metadata": {
  "kernelspec": {
   "display_name": "Python 3",
   "language": "python",
   "name": "python3"
  },
  "language_info": {
   "codemirror_mode": {
    "name": "ipython",
    "version": 3
   },
   "file_extension": ".py",
   "mimetype": "text/x-python",
   "name": "python",
   "nbconvert_exporter": "python",
   "pygments_lexer": "ipython3",
   "version": "3.6.5"
  }
 },
 "nbformat": 4,
 "nbformat_minor": 2
}
